Workbook

Sheet CEBAS ION2768
A1: Codigo CEBAS | C1: Codigo DeWood
A2: ION2768-1 | B2: 2768-1 | C2: 114
A3: 13 | B3: =_xlfn.CONCAT(RIGHT(LEFT($A$2,7),4),"-",A3) -> 2768-13 | C3: 382
A4: 3 | B4: =_xlfn.CONCAT(RIGHT(LEFT($A$2,7),4),"-",A4) -> 2768-3 | C4: 37
A5: 2 | B5: =_xlfn.CONCAT(RIGHT(LEFT($A$2,7),4),"-",A5) -> 2768-2 | C5: 364
A6: 16 | B6: =_xlfn.CONCAT(RIGHT(LEFT($A$2,7),4),"-",A6) -> 2768-16 | C6: 190
A7: 11 | B7: =_xlfn.CONCAT(RIGHT(LEFT($A$2,7),4),"-",A7) -> 2768-11 | C7: 381
A8: 15 | B8: =_xlfn.CONCAT(RIGHT(LEFT($A$2,7),4),"-",A8) -> 2768-15 | C8: 176
A9: 12 | B9: =_xlfn.CONCAT(RIGHT(LEFT($A$2,7),4),"-",A9) -> 2768-12 | C9: 75
A10: 9 | B10: =_xlfn.CONCAT(RIGHT(LEFT($A$2,7),4),"-",A10) -> 2768-9 | C10: 137
A11: 18 | B11: =_xlfn.CONCAT(RIGHT(LEFT($A$2,7),4),"-",A11) -> 2768-18 | C11: 1085
A12: 4 | B12: =_xlfn.CONCAT(RIGHT(LEFT($A$2,7),4),"-",A12) -> 2768-4 | C12: 172
A13: 10 | B13: =_xlfn.CONCAT(RIGHT(LEFT($A$2,7),4),"-",A13) -> 2768-10 | C13: 1090
A14: 7 | B14: =_xlfn.CONCAT(RIGHT(LEFT($A$2,7),4),"-",A14) -> 2768-7 | C14: 1011
... A46: 139 | B46: =_xlfn.CONCAT(RIGHT(LEFT($A$2,7),4),"-",A46) -> 2768-139 | C46: 325
A47: 65 | B47: =_xlfn.CONCAT(RIGHT(LEFT($A$2,7),4),"-",A47) -> 2768-65 | C47: 360?
A48: 124 | B48: =_xlfn.CONCAT(RIGHT(LEFT($A$2,7),4),"-",A48) -> 2768-124 | C48: 1075
A49: 269 | B49: =_xlfn.CONCAT(RIGHT(LEFT($A$2,7),4),"-",A49) -> 2768-269 | C49: 82
A50: 147 | B50: =_xlfn.CONCAT(RIGHT(LEFT($A$2,7),4),"-",A50) -> 2768-147 | C50: 1083
A51: 150 | B51: =_xlfn.CONCAT(RIGHT(LEFT($A$2,7),4),"-",A51) -> 2768-150 | C51: 1012
A52: 270 | B52: =_xlfn.CONCAT(RIGHT(LEFT($A$2,7),4),"-",A52) -> 2768-270 | C52: 143
A53: 71 | B53: =_xlfn.CONCAT(RIGHT(LEFT($A$2,7),4),"-",A53) -> 2768-71 | C53: 142
A54: 145 | B54: =_xlfn.CONCAT(RIGHT(LEFT($A$2,7),4),"-",A54) -> 2768-145 | C54: 346
A55: 123 | B55: =_xlfn.CONCAT(RIGHT(LEFT($A$2,7),4),"-",A55) -> 2768-123 | C55: 332
A56: 96 | B56: =_xlfn.CONCAT(RIGHT(LEFT($A$2,7),4),"-",A56) -> 2768-96 | C56: 146
A57: 148 | B57: =_xlfn.CONCAT(RIGHT(LEFT($A$2,7),4),"-",A57) -> 2768-148 | C57: 328
A58: 151 | B58: =_xlfn.CONCAT(RIGHT(LEFT($A$2,7),4),"-",A58) -> 2768-151 | C58: 128
A59: 137 | B59: =_xlfn.CONCAT(RIGHT(LEFT($A$2,7),4),"-",A59) -> 2768-137 | C59: 135
... A268: 113 | B268: =_xlfn.CONCAT(RIGHT(LEFT($A$2,7),4),"-",A268) -> 2768-113 | C268: 333
A269: ….............. | B269: =_xlfn.CONCAT(RIGHT(LEFT($A$2,7),4),"-",A269) -> 2768-….............. | C269: ….............. | E269: Faltan 4¿?
A270: ….............. | B270: =_xlfn.CONCAT(RIGHT(LEFT($A$2,7),4),"-",A270) -> 2768-….............. | C270: …..............
A271: ….............. | B271: =_xlfn.CONCAT(RIGHT(LEFT($A$2,7),4),"-",A271) -> 2768-….............. | C271: …..............
A272: ….............. | B272: =_xlfn.CONCAT(RIGHT(LEFT($A$2,7),4),"-",A272) -> 2768-….............. | C272: …..............

Sheet CEBAS ION2775
A1: ION2775-
A2: 24 | B2: =_xlfn.CONCAT(RIGHT(LEFT($A$1,7),4),"-",A2) -> 2775-24 | C2: 42
A3: 13 | B3: =_xlfn.CONCAT(RIGHT(LEFT($A$1,7),4),"-",A3) -> 2775-13 | C3: 1034
A4: 28 | B4: =_xlfn.CONCAT(RIGHT(LEFT($A$1,7),4),"-",A4) -> 2775-28 | C4: 130
A5: 16 | B5: =_xlfn.CONCAT(RIGHT(LEFT($A$1,7),4),"-",A5) -> 2775-16 | C5: 1025
A6: 30 | B6: =_xlfn.CONCAT(RIGHT(LEFT($A$1,7),4),"-",A6) -> 2775-30 | C6: 170
A7: 14 | B7: =_xlfn.CONCAT(RIGHT(LEFT($A$1,7),4),"-",A7) -> 2775-14 | C7: 1058
A8: 9 | B8: =_xlfn.CONCAT(RIGHT(LEFT($A$1,7),4),"-",A8) -> 2775-9 | C8: 378
A9: 23 | B9: =_xlfn.CONCAT(RIGHT(LEFT($A$1,7),4),"-",A9) -> 2775-23 | C9: 1015
A10: 17 | B10: =_xlfn.CONCAT(RIGHT(LEFT($A$1,7),4),"-",A10) -> 2775-17 | C10: 331
A11: 7 | B11: =_xlfn.CONCAT(RIGHT(LEFT($A$1,7),4),"-",A11) -> 2775-7 | C11: 1010
A12: 1 | B12: =_xlfn.CONCAT(RIGHT(LEFT($A$1,7),4),"-",A12) -> 2775-1 | C12: 187
A13: 4 | B13: =_xlfn.CONCAT(RIGHT(LEFT($A$1,7),4),"-",A13) -> 2775-4 | C13: 1057
... A29: 5 | B29: =_xlfn.CONCAT(RIGHT(LEFT($A$1,7),4),"-",A29) -> 2775-5 | C29: 1013
A30: …......... | B30: =_xlfn.CONCAT(RIGHT(LEFT($A$1,7),4),"-",A30) -> 2775-…......... | C30: …......... | D30: Faltan 2
A31: …......... | B31: =_xlfn.CONCAT(RIGHT(LEFT($A$1,7),4),"-",A31) -> 2775-…......... | C31: ….........

Sheet Hoja1
A3: Etiquetas de fila | B3: Promedio de Total Klassen lignin | C3: Desvest de Total Klassen lignin
A4: 1 | B4: 41.32223 | C4: 19.857375
A5: AA | B5: 41.592404 | C5: 18.41449
A6: FS | B6: 40.781883 | C6: 24.831352
A7: 2 | B7: 24.795071 | C7: 12.086914
A8: AA | B8: 27.44948 | C8: 13.484657
A9: FS | B9: 18.159047 | C9: 5.0905665
A10: 4 | B10: 39.317596 | C10: 23.083286
A11: AA | B11: 30.244272 | C11: 24.387996
A12: FS | B12: 52.927581 | C12: 13.032431
A13: Total general | B13: 37.382781 | C13: 20.585056

Sheet LIGNIN BILBAO
A1: Sample | B1: T (w/o cap) | C1: DW | D1: SampleCheck | E1: Dried sample W | F1: Non-soluble lignin (mg) | G1: 2 | H1: Dried Sample Corrected with tube | I1: Non-soluble lignin (mg) | J1: 3 | K1: Non soluble Lignin/100mg sample | L1: Soluble Lignin /100 mg | M1: Total Klassen lignin | N1: Code | O1: Species | P1: Diameter | Q1: Class
A2: 120 | B2: 11.4819 | C2: 116.7 | D2: =VLOOKUP(A2,'Lignin measurement Plates'!B$72:B$121,1,FALSE) -> 120 | E2: =VLOOKUP(A2,'Dried samples '!E$2:F$51,2,FALSE) -> 11.5409 | F2: =(E2-B2)*1000 -> 59 | G2: =C2-F2 -> 57.7 | H2: =E2-E$64 -> 11.53482 | I2: =(H2-B2)*1000 -> 52.92 | J2: =C2-I2 -> 63.78 | K2: =(J2/C2)*100 -> 54.652956 | L2: =VLOOKUP(A2,'Lignin measurement Plates'!D$182:F$231,2,FALSE) -> 0.10204856 | M2: =L2+K2 -> 54.755005 | N2: =VLOOKUP(A2,Hoja2!A$2:B$872,2,FALSE) -> 10-P1S4C4FS | O2: =IF(LEN('LIGNIN BILBAO'!N2)>6,RIGHT(LEFT('LIGNIN BILBAO'!N2,11),2),RIGHT((LEFT(N2,4)),2)) -> FS | P2: =IF(LEN('LIGNIN BILBAO'!$N2)>6,LEFT(N2,2),1) -> 10 | Q2: =IF(LEN('LIGNIN BILBAO'!$N2)>6,RIGHT(LEFT('LIGNIN BILBAO'!$N2,9),1),RIGHT(N2,1)) -> 4 | V2: =VLOOKUP(A2,Z$31:Z$80,1,FALSE) -> 120
A3: 157 | B3: 11.5596 | C3: 124.7 | D3: =VLOOKUP(A3,'Lignin measurement Plates'!B$72:B$121,1,FALSE) -> 157 | E3: =VLOOKUP(A3,'Dried samples '!E$2:F$51,2,FALSE) -> 11.6249 | F3: =(E3-B3)*1000 -> 65.3 | G3: =C3-F3 -> 59.4 | H3: =E3-E$64 -> 11.61882 | I3: =(H3-B3)*1000 -> 59.22 | J3: =C3-I3 -> 65.48 | K3: =(J3/C3)*100 -> 52.510024 | L3: =VLOOKUP(A3,'Lignin measurement Plates'!D$182:F$231,2,FALSE) -> 0.10653029 | M3: =L3+K3 -> 52.616554 | N3: =VLOOKUP(A3,Hoja2!A$2:B$872,2,FALSE) -> 10-P3S2C4FS | O3: =IF(LEN('LIGNIN BILBAO'!N3)>6,RIGHT(LEFT('LIGNIN BILBAO'!N3,11),2),RIGHT((LEFT(N3,4)),2)) -> FS | P3: =IF(LEN('LIGNIN BILBAO'!$N3)>6,LEFT(N3,2),1) -> 10 | Q3: =IF(LEN('LIGNIN BILBAO'!$N3)>6,RIGHT(LEFT('LIGNIN BILBAO'!$N3,9),1),RIGHT(N3,1)) -> 4 | V3: =VLOOKUP(A3,Z$31:Z$80,1,FALSE) -> 157
A4: 409 | B4: 11.4826 | C4: 118.7 | D4: =VLOOKUP(A4,'Lignin measurement Plates'!B$72:B$121,1,FALSE) -> 409 | E4: =VLOOKUP(A4,'Dried samples '!E$2:F$51,2,FALSE) -> 11.5635 | F4: =(E4-B4)*1000 -> 80.9 | G4: =C4-F4 -> 37.8 | H4: =E4-E$64 -> 11.55742 | I4: =(H4-B4)*1000 -> 74.82 | J4: =C4-I4 -> 43.88 | K4: =(J4/C4)*100 -> 36.967144 | L4: =VLOOKUP(A4,'Lignin measurement Plates'!D$182:F$231,2,FALSE) -> 0.093394121 | M4: =L4+K4 -> 37.060538 | N4: =VLOOKUP(A4,Hoja2!A$2:B$872,2,FALSE) -> 10-P6S5C1FS -b | O4: =IF(LEN('LIGNIN BILBAO'!N4)>6,RIGHT(LEFT('LIGNIN BILBAO'!N4,11),2),RIGHT((LEFT(N4,4)),2)) -> FS | P4: =IF(LEN('LIGNIN BILBAO'!$N4)>6,LEFT(N4,2),1) -> 10 | Q4: =IF(LEN('LIGNIN BILBAO'!$N4)>6,RIGHT(LEFT('LIGNIN BILBAO'!$N4,9),1),RIGHT(N4,1)) -> 1 | V4: =VLOOKUP(A4,Z$31:Z$80,1,FALSE) -> 409
A5: 84 | B5: 11.4655 | C5: 131.7 | D5: =VLOOKUP(A5,'Lignin measurement Plates'!B$72:B$121,1,FALSE) -> 84 | E5: =VLOOKUP(A5,'Dried samples '!E$2:F$51,2,FALSE) -> 11.527 | F5: =(E5-B5)*1000 -> 61.5 | G5: =C5-F5 -> 70.2 | H5: =E5-E$64 -> 11.52092 | I5: =(H5-B5)*1000 -> 55.42 | J5: =C5-I5 -> 76.28 | K5: =(J5/C5)*100 -> 57.919514 | L5: =VLOOKUP(A5,'Lignin measurement Plates'!D$182:F$231,2,FALSE) -> 0.088816318 | M5: =L5+K5 -> 58.00833 | N5: =VLOOKUP(A5,Hoja2!A$2:B$872,2,FALSE) -> 10-P1S3C4FS | O5: =IF(LEN('LIGNIN BILBAO'!N5)>6,RIGHT(LEFT('LIGNIN BILBAO'!N5,11),2),RIGHT((LEFT(N5,4)),2)) -> FS | P5: =IF(LEN('LIGNIN BILBAO'!$N5)>6,LEFT(N5,2),1) -> 10 | Q5: =IF(LEN('LIGNIN BILBAO'!$N5)>6,RIGHT(LEFT('LIGNIN BILBAO'!$N5,9),1),RIGHT(N5,1)) -> 4 | V5: =VLOOKUP(A5,Z$31:Z$80,1,FALSE) -> 84
A6: 118 | B6: 11.4395 | C6: 113.3 | D6: =VLOOKUP(A6,'Lignin measurement Plates'!B$72:B$121,1,FALSE) -> 118 | E6: =VLOOKUP(A6,'Dried samples '!E$2:F$51,2,FALSE) -> 11.478 | F6: =(E6-B6)*1000 -> 38.5 | G6: =C6-F6 -> 74.8 | H6: =E6-E$64 -> 11.47192 | I6: =(H6-B6)*1000 -> 32.42 | J6: =C6-I6 -> 80.88 | K6: =(J6/C6)*100 -> 71.385702 | L6: =VLOOKUP(A6,'Lignin measurement Plates'!D$182:F$231,2,FALSE) -> 0.089927262 | M6: =L6+K6 -> 71.475629 | N6: =VLOOKUP(A6,Hoja2!A$2:B$872,2,FALSE) -> 10-P1S4C1FS | O6: =IF(LEN('LIGNIN BILBAO'!N6)>6,RIGHT(LEFT('LIGNIN BILBAO'!N6,11),2),RIGHT((LEFT(N6,4)),2)) -> FS | P6: =IF(LEN('LIGNIN BILBAO'!$N6)>6,LEFT(N6,2),1) -> 10 | Q6: =IF(LEN('LIGNIN BILBAO'!$N6)>6,RIGHT(LEFT('LIGNIN BILBAO'!$N6,9),1),RIGHT(N6,1)) -> 1 | V6: =VLOOKUP(A6,Z$31:Z$80,1,FALSE) -> 118
A7: 373 | B7: 11.5601 | C7: 138.7 | D7: =VLOOKUP(A7,'Lignin measurement Plates'!B$72:B$121,1,FALSE) -> 373 | E7: =VLOOKUP(A7,'Dried samples '!E$2:F$51,2,FALSE) -> 11.6334 | F7: =(E7-B7)*1000 -> 73.3 | G7: =C7-F7 -> 65.4 | H7: =E7-E$64 -> 11.62732 | I7: =(H7-B7)*1000 -> 67.22 | J7: =C7-I7 -> 71.48 | K7: =(J7/C7)*100 -> 51.535689 | L7: =VLOOKUP(A7,'Lignin measurement Plates'!D$182:F$231,2,FALSE) -> 0.084831424 | M7: =L7+K7 -> 51.62052 | N7: =VLOOKUP(A7,Hoja2!A$2:B$872,2,FALSE) -> 10-P6S3C1FS -b | O7: =IF(LEN('LIGNIN BILBAO'!N7)>6,RIGHT(LEFT('LIGNIN BILBAO'!N7,11),2),RIGHT((LEFT(N7,4)),2)) -> FS | P7: =IF(LEN('LIGNIN BILBAO'!$N7)>6,LEFT(N7,2),1) -> 10 | Q7: =IF(LEN('LIGNIN BILBAO'!$N7)>6,RIGHT(LEFT('LIGNIN BILBAO'!$N7,9),1),RIGHT(N7,1)) -> 1 | V7: =VLOOKUP(A7,Z$31:Z$80,1,FALSE) -> 373
A8: 355 | B8: 11.4847 | C8: 207.4 | D8: =VLOOKUP(A8,'Lignin measurement Plates'!B$72:B$121,1,FALSE) -> 355 | E8: =VLOOKUP(A8,'Dried samples '!E$2:F$51,2,FALSE) -> 11.6148 | F8: =(E8-B8)*1000 -> 130.1 | G8: =C8-F8 -> 77.3 | H8: =E8-E$64 -> 11.60872 | I8: =(H8-B8)*1000 -> 124.02 | J8: =C8-I8 -> 83.38 | K8: =(J8/C8)*100 -> 40.202507 | L8: =VLOOKUP(A8,'Lignin measurement Plates'!D$182:F$231,2,FALSE) -> 0.087390793 | M8: =L8+K8 -> 40.289898 | N8: =VLOOKUP(A8,Hoja2!A$2:B$872,2,FALSE) -> 10-P6S2C1FS -b | O8: =IF(LEN('LIGNIN BILBAO'!N8)>6,RIGHT(LEFT('LIGNIN BILBAO'!N8,11),2),RIGHT((LEFT(N8,4)),2)) -> FS | P8: =IF(LEN('LIGNIN BILBAO'!$N8)>6,LEFT(N8,2),1) -> 10 | Q8: =IF(LEN('LIGNIN BILBAO'!$N8)>6,RIGHT(LEFT('LIGNIN BILBAO'!$N8,9),1),RIGHT(N8,1)) -> 1 | V8: =VLOOKUP(A8,Z$31:Z$80,1,FALSE) -> 355
A9: 368 | B9: 11.4946 | C9: 109.6 | D9: =VLOOKUP(A9,'Lignin measurement Plates'!B$72:B$121,1,FALSE) -> 368 | E9: =VLOOKUP(A9,'Dried samples '!E$2:F$51,2,FALSE) -> 11.5561 | F9: =(E9-B9)*1000 -> 61.5 | G9: =C9-F9 -> 48.1 | H9: =E9-E$64 -> 11.55002 | I9: =(H9-B9)*1000 -> 55.42 | J9: =C9-I9 -> 54.18 | K9: =(J9/C9)*100 -> 49.434307 | L9: =VLOOKUP(A9,'Lignin measurement Plates'!D$182:F$231,2,FALSE) -> 0.016370865 | M9: =L9+K9 -> 49.450677 | N9: =VLOOKUP(A9,Hoja2!A$2:B$872,2,FALSE) -> 10-P6S3C2AA | O9: =IF(LEN('LIGNIN BILBAO'!N9)>6,RIGHT(LEFT('LIGNIN BILBAO'!N9,11),2),RIGHT((LEFT(N9,4)),2)) -> AA | P9: =IF(LEN('LIGNIN BILBAO'!$N9)>6,LEFT(N9,2),1) -> 10 | Q9: =IF(LEN('LIGNIN BILBAO'!$N9)>6,RIGHT(LEFT('LIGNIN BILBAO'!$N9,9),1),RIGHT(N9,1)) -> 2 | V9: =VLOOKUP(A9,Z$31:Z$80,1,FALSE) -> 368
A10: 142 | B10: 11.4493 | C10: 104.2 | D10: =VLOOKUP(A10,'Lignin measurement Plates'!B$72:B$121,1,FALSE) -> 142 | E10: =VLOOKUP(A10,'Dried samples '!E$2:F$51,2,FALSE) -> 11.5116 | F10: =(E10-B10)*1000 -> 62.3 | G10: =C10-F10 -> 41.9 | H10: =E10-E$64 -> 11.50552 | I10: =(H10-B10)*1000 -> 56.22 | J10: =C10-I10 -> 47.98 | K10: =(J10/C10)*100 -> 46.046065 | L10: =VLOOKUP(A10,'Lignin measurement Plates'!D$182:F$231,2,FALSE) -> 0.033303183 | M10: =L10+K10 -> 46.079368 | N10: =VLOOKUP(A10,Hoja2!A$2:B$872,2,FALSE) -> 10-P3S1C4AA | O10: =IF(LEN('LIGNIN BILBAO'!N10)>6,RIGHT(LEFT('LIGNIN BILBAO'!N10,11),2),RIGHT((LEFT(N10,4)),2)) -> AA | P10: =IF(LEN('LIGNIN BILBAO'!$N10)>6,LEFT(N10,2),1) -> 10 | Q10: =IF(LEN('LIGNIN BILBAO'!$N10)>6,RIGHT(LEFT('LIGNIN BILBAO'!$N10,9),1),RIGHT(N10,1)) -> 4 | V10: =VLOOKUP(A10,Z$31:Z$80,1,FALSE) -> 142
A11: 385 | B11: 11.4272 | C11: 112 | D11: =VLOOKUP(A11,'Lignin measurement Plates'!B$72:B$121,1,FALSE) -> 385 | E11: =VLOOKUP(A11,'Dried samples '!E$2:F$51,2,FALSE) -> 11.4893 | F11: =(E11-B11)*1000 -> 62.1 | G11: =C11-F11 -> 49.9 | H11: =E11-E$64 -> 11.48322 | I11: =(H11-B11)*1000 -> 56.02 | J11: =C11-I11 -> 55.98 | K11: =(J11/C11)*100 -> 49.982143 | L11: =VLOOKUP(A11,'Lignin measurement Plates'!D$182:F$231,2,FALSE) -> 0.01522786 | M11: =L11+K11 -> 49.997371 | N11: =VLOOKUP(A11,Hoja2!A$2:B$872,2,FALSE) -> 10-P6S4C1AA -b | O11: =IF(LEN('LIGNIN BILBAO'!N11)>6,RIGHT(LEFT('LIGNIN BILBAO'!N11,11),2),RIGHT((LEFT(N11,4)),2)) -> AA | P11: =IF(LEN('LIGNIN BILBAO'!$N11)>6,LEFT(N11,2),1) -> 10 | Q11: =IF(LEN('LIGNIN BILBAO'!$N11)>6,RIGHT(LEFT('LIGNIN BILBAO'!$N11,9),1),RIGHT(N11,1)) -> 1 | V11: =VLOOKUP(A11,Z$31:Z$80,1,FALSE) -> 385
A12: 331 | B12: 11.5023 | C12: 118.2 | D12: =VLOOKUP(A12,'Lignin measurement Plates'!B$72:B$121,1,FALSE) -> 331 | E12: =VLOOKUP(A12,'Dried samples '!E$2:F$51,2,FALSE) -> 11.5666 | F12: =(E12-B12)*1000 -> 64.3 | G12: =C12-F12 -> 53.9 | H12: =E12-E$64 -> 11.56052 | I12: =(H12-B12)*1000 -> 58.22 | J12: =C12-I12 -> 59.98 | K12: =(J12/C12)*100 -> 50.744501 | L12: =VLOOKUP(A12,'Lignin measurement Plates'!D$182:F$231,2,FALSE) -> 0.013511648 | M12: =L12+K12 -> 50.758012 | N12: =VLOOKUP(A12,Hoja2!A$2:B$872,2,FALSE) -> 10-P6S1C1AA -b | O12: =IF(LEN('LIGNIN BILBAO'!N12)>6,RIGHT(LEFT('LIGNIN BILBAO'!N12,11),2),RIGHT((LEFT(N12,4)),2)) -> AA | P12: =IF(LEN('LIGNIN BILBAO'!$N12)>6,LEFT(N12,2),1) -> 10 | Q12: =IF(LEN('LIGNIN BILBAO'!$N12)>6,RIGHT(LEFT('LIGNIN BILBAO'!$N12,9),1),RIGHT(N12,1)) -> 1 | V12: =VLOOKUP(A12,Z$31:Z$80,1,FALSE) -> 331
A13: 127 | B13: 11.4607 | C13: 110.4 | D13: =VLOOKUP(A13,'Lignin measurement Plates'!B$72:B$121,1,FALSE) -> 127 | E13: =VLOOKUP(A13,'Dried samples '!E$2:F$51,2,FALSE) -> 11.5242 | F13: =(E13-B13)*1000 -> 63.5 | G13: =C13-F13 -> 46.9 | H13: =E13-E$64 -> 11.51812 | I13: =(H13-B13)*1000 -> 57.42 | J13: =C13-I13 -> 52.98 | K13: =(J13/C13)*100 -> 47.98913 | L13: =VLOOKUP(A13,'Lignin measurement Plates'!D$182:F$231,2,FALSE) -> 0.015939693 | M13: =L13+K13 -> 48.00507 | N13: =VLOOKUP(A13,Hoja2!A$2:B$872,2,FALSE) -> 10-P1S5C1AA | O13: =IF(LEN('LIGNIN BILBAO'!N13)>6,RIGHT(LEFT('LIGNIN BILBAO'!N13,11),2),RIGHT((LEFT(N13,4)),2)) -> AA | P13: =IF(LEN('LIGNIN BILBAO'!$N13)>6,LEFT(N13,2),1) -> 10 | Q13: =IF(LEN('LIGNIN BILBAO'!$N13)>6,RIGHT(LEFT('LIGNIN BILBAO'!$N13,9),1),RIGHT(N13,1)) -> 1 | V13: =VLOOKUP(A13,Z$31:Z$80,1,FALSE) -> 127
A14: 146 | B14: 11.4411 | C14: 115.5 | D14: =VLOOKUP(A14,'Lignin measurement Plates'!B$72:B$121,1,FALSE) -> 146 | E14: =VLOOKUP(A14,'Dried samples '!E$2:F$51,2,FALSE) -> 11.5568 | F14: =(E14-B14)*1000 -> 115.7 | G14: =C14-F14 -> -0.2 | H14: =E14-E$64 -> 11.55072 | I14: =(H14-B14)*1000 -> 109.62 | J14: =C14-I14 -> 5.88 | K14: =(J14/C14)*100 -> 5.0909091 | L14: =VLOOKUP(A14,'Lignin measurement Plates'!D$182:F$231,2,FALSE) -> 0.021424097 | M14: =L14+K14 -> 5.1123332 | N14: =VLOOKUP(A14,Hoja2!A$2:B$872,2,FALSE) -> 25-P3S2C1AA | O14: =IF(LEN('LIGNIN BILBAO'!N14)>6,RIGHT(LEFT('LIGNIN BILBAO'!N14,11),2),RIGHT((LEFT(N14,4)),2)) -> AA | P14: =IF(LEN('LIGNIN BILBAO'!$N14)>6,LEFT(N14,2),1) -> 25 | Q14: =IF(LEN('LIGNIN BILBAO'!$N14)>6,RIGHT(LEFT('LIGNIN BILBAO'!$N14,9),1),RIGHT(N14,1)) -> 1 | V14: =VLOOKUP(A14,Z$31:Z$80,1,FALSE) -> 146 | Z14: 1023 | AA14: 11.5091 | AB14: 144.4 | AC14: 1023 | AD14: 11.676 | AE14: 166.9 | AF14: -22.5
A15: 7 | B15: 11.483 | C15: 109.5 | D15: =VLOOKUP(A15,'Lignin measurement Plates'!B$72:B$121,1,FALSE) -> 7 | E15: =VLOOKUP(A15,'Dried samples '!E$2:F$51,2,FALSE) -> 11.5268 | F15: =(E15-B15)*1000 -> 43.8 | G15: =C15-F15 -> 65.7 | H15: =E15-E$64 -> 11.52072 | I15: =(H15-B15)*1000 -> 37.72 | J15: =C15-I15 -> 71.78 | K15: =(J15/C15)*100 -> 65.552511 | L15: =VLOOKUP(A15,'Lignin measurement Plates'!D$182:F$231,2,FALSE) -> 0.014540161 | M15: =L15+K15 -> 65.567052 | N15: =VLOOKUP(A15,Hoja2!A$2:B$872,2,FALSE) -> 10-P1S1C1AA | O15: =IF(LEN('LIGNIN BILBAO'!N15)>6,RIGHT(LEFT('LIGNIN BILBAO'!N15,11),2),RIGHT((LEFT(N15,4)),2)) -> AA | P15: =IF(LEN('LIGNIN BILBAO'!$N15)>6,LEFT(N15,2),1) -> 10 | Q15: =IF(LEN('LIGNIN BILBAO'!$N15)>6,RIGHT(LEFT('LIGNIN BILBAO'!$N15,9),1),RIGHT(N15,1)) -> 1 | V15: =VLOOKUP(A15,Z$31:Z$80,1,FALSE) -> 7 | Z15: 75 | AA15: 11.5125 | AB15: 107.2 | AC15: 75 | AD15: 11.6677 | AE15: 155.2 | AF15: -48
A16: 176 | B16: 11.4049 | C16: 137.6 | D16: =VLOOKUP(A16,'Lignin measurement Plates'!B$72:B$121,1,FALSE) -> 176 | E16: =VLOOKUP(A16,'Dried samples '!E$2:F$51,2,FALSE) -> 11.5654 | F16: =(E16-B16)*1000 -> 160.5 | G16: =C16-F16 -> -22.9 | H16: =E16-E$64 -> 11.55932 | I16: =(H16-B16)*1000 -> 154.42 | J16: =C16-I16 -> -16.82 | K16: =(J16/C16)*100 -> -12.223837 | L16: =VLOOKUP(A16,'Lignin measurement Plates'!D$182:F$231,2,FALSE) -> 0.042772703 | N16: =VLOOKUP(A16,Hoja2!A$2:B$872,2,FALSE) -> 10-P3S4C1AA | O16: =IF(LEN('LIGNIN BILBAO'!N16)>6,RIGHT(LEFT('LIGNIN BILBAO'!N16,11),2),RIGHT((LEFT(N16,4)),2)) -> AA | P16: =IF(LEN('LIGNIN BILBAO'!$N16)>6,LEFT(N16,2),1) -> 10 | Q16: =IF(LEN('LIGNIN BILBAO'!$N16)>6,RIGHT(LEFT('LIGNIN BILBAO'!$N16,9),1),RIGHT(N16,1)) -> 1 | V16: =VLOOKUP(A16,Z$31:Z$80,1,FALSE) -> 176 | Z16: 396 | AA16: 11.4609 | AB16: 159.1 | AC16: 396 | AD16: 11.637 | AE16: 176.1 | AF16: -17
A17: 708 | B17: 11.4801 | C17: 124 | D17: =VLOOKUP(A17,'Lignin measurement Plates'!B$72:B$121,1,FALSE) -> 708 | E17: =VLOOKUP(A17,'Dried samples '!E$2:F$51,2,FALSE) -> 11.5782 | F17: =(E17-B17)*1000 -> 98.1 | G17: =C17-F17 -> 25.9 | H17: =E17-E$64 -> 11.57212 | I17: =(H17-B17)*1000 -> 92.02 | J17: =C17-I17 -> 31.98 | K17: =(J17/C17)*100 -> 25.790323 | L17: =VLOOKUP(A17,'Lignin measurement Plates'!D$182:F$231,2,FALSE) -> 0.026156824 | M17: =L17+K17 -> 25.816479 | N17: =VLOOKUP(A17,Hoja2!A$2:B$872,2,FALSE) -> 10-P2S4C1AA | O17: =IF(LEN('LIGNIN BILBAO'!N17)>6,RIGHT(LEFT('LIGNIN BILBAO'!N17,11),2),RIGHT((LEFT(N17,4)),2)) -> AA | P17: =IF(LEN('LIGNIN BILBAO'!$N17)>6,LEFT(N17,2),1) -> 10 | Q17: =IF(LEN('LIGNIN BILBAO'!$N17)>6,RIGHT(LEFT('LIGNIN BILBAO'!$N17,9),1),RIGHT(N17,1)) -> 1 | V17: =VLOOKUP(A17,Z$31:Z$80,1,FALSE) -> 708
A18: 189 | B18: 11.4805 | C18: 166.4 | D18: =VLOOKUP(A18,'Lignin measurement Plates'!B$72:B$121,1,FALSE) -> 189 | E18: =VLOOKUP(A18,'Dried samples '!E$2:F$51,2,FALSE) -> 11.6185 | F18: =(E18-B18)*1000 -> 138 | G18: =C18-F18 -> 28.4 | H18: =E18-E$64 -> 11.61242 | I18: =(H18-B18)*1000 -> 131.92 | J18: =C18-I18 -> 34.48 | K18: =(J18/C18)*100 -> 20.721154 | L18: =VLOOKUP(A18,'Lignin measurement Plates'!D$182:F$231,2,FALSE) -> 0.017921851 | M18: =L18+K18 -> 20.739076 | N18: =VLOOKUP(A18,Hoja2!A$2:B$872,2,FALSE) -> 10-P3S5C2AA | O18: =IF(LEN('LIGNIN BILBAO'!N18)>6,RIGHT(LEFT('LIGNIN BILBAO'!N18,11),2),RIGHT((LEFT(N18,4)),2)) -> AA | P18: =IF(LEN('LIGNIN BILBAO'!$N18)>6,LEFT(N18,2),1) -> 10 | Q18: =IF(LEN('LIGNIN BILBAO'!$N18)>6,RIGHT(LEFT('LIGNIN BILBAO'!$N18,9),1),RIGHT(N18,1)) -> 2 | V18: =VLOOKUP(A18,Z$31:Z$80,1,FALSE) -> 189
A19: 1047 | B19: 11.405 | C19: 122.5 | D19: =VLOOKUP(A19,'Lignin measurement Plates'!B$72:B$121,1,FALSE) -> 1047 | E19: =VLOOKUP(A19,'Dried samples '!E$2:F$51,2,FALSE) -> 11.5905 | F19: =(E19-B19)*1000 -> 185.5 | G19: =C19-F19 -> -63 | H19: =E19-E$64 -> 11.58442 | I19: =(H19-B19)*1000 -> 179.42 | J19: =C19-I19 -> -56.92 | K19: =(J19/C19)*100 -> -46.465306 | L19: =VLOOKUP(A19,'Lignin measurement Plates'!D$182:F$231,2,FALSE) -> 0.095164695 | N19: =VLOOKUP(A19,Hoja2!A$2:B$872,2,FALSE) -> 64FS2 | O19: =IF(LEN('LIGNIN BILBAO'!N19)>6,RIGHT(LEFT('LIGNIN BILBAO'!N19,11),2),RIGHT((LEFT(N19,4)),2)) -> FS | P19: =IF(LEN('LIGNIN BILBAO'!$N19)>6,LEFT(N19,2),1) -> 1 | Q19: =IF(LEN('LIGNIN BILBAO'!$N19)>6,RIGHT(LEFT('LIGNIN BILBAO'!$N19,9),1),RIGHT(N19,1)) -> 2 | V19: =VLOOKUP(A19,Z$31:Z$80,1,FALSE) -> 1047 | Z19: 1023 | AA19: 11.5091 | AB19: 144.4 | AC19: 1023 | AD19: 11.6324 | AE19: 123.3 | AF19: 21.1
A20: 1070 | B20: 11.503 | C20: 150.5 | D20: =VLOOKUP(A20,'Lignin measurement Plates'!B$72:B$121,1,FALSE) -> 1070 | E20: =VLOOKUP(A20,'Dried samples '!E$2:F$51,2,FALSE) -> 11.6545 | F20: =(E20-B20)*1000 -> 151.5 | G20: =C20-F20 -> -1 | H20: =E20-E$64 -> 11.64842 | I20: =(H20-B20)*1000 -> 145.42 | J20: =C20-I20 -> 5.08 | K20: =(J20/C20)*100 -> 3.3754153 | L20: =VLOOKUP(A20,'Lignin measurement Plates'!D$182:F$231,2,FALSE) -> 0.087416392 | M20: =L20+K20 -> 3.4628317 | N20: =VLOOKUP(A20,Hoja2!A$2:B$872,2,FALSE) -> 33FS1 | O20: =IF(LEN('LIGNIN BILBAO'!N20)>6,RIGHT(LEFT('LIGNIN BILBAO'!N20,11),2),RIGHT((LEFT(N20,4)),2)) -> FS | P20: =IF(LEN('LIGNIN BILBAO'!$N20)>6,LEFT(N20,2),1) -> 1 | Q20: =IF(LEN('LIGNIN BILBAO'!$N20)>6,RIGHT(LEFT('LIGNIN BILBAO'!$N20,9),1),RIGHT(N20,1)) -> 1 | V20: =VLOOKUP(A20,Z$31:Z$80,1,FALSE) -> 1070 | Z20: 75 | AA20: 11.5125 | AB20: 107.2 | AC20: 75 | AD20: 11.622 | AE20: 109.5 | AF20: -2.3
A21: 1048 | B21: 11.5105 | C21: 136.2 | D21: =VLOOKUP(A21,'Lignin measurement Plates'!B$72:B$121,1,FALSE) -> 1048 | E21: =VLOOKUP(A21,'Dried samples '!E$2:F$51,2,FALSE) -> 11.5658 | F21: =(E21-B21)*1000 -> 55.3 | G21: =C21-F21 -> 80.9 | H21: =E21-E$64 -> 11.55972 | I21: =(H21-B21)*1000 -> 49.22 | J21: =C21-I21 -> 86.98 | K21: =(J21/C21)*100 -> 63.861968 | L21: =VLOOKUP(A21,'Lignin measurement Plates'!D$182:F$231,2,FALSE) -> 0.093952509 | M21: =L21+K21 -> 63.95592 | N21: =VLOOKUP(A21,Hoja2!A$2:B$872,2,FALSE) -> 64FS4 | O21: =IF(LEN('LIGNIN BILBAO'!N21)>6,RIGHT(LEFT('LIGNIN BILBAO'!N21,11),2),RIGHT((LEFT(N21,4)),2)) -> FS | P21: =IF(LEN('LIGNIN BILBAO'!$N21)>6,LEFT(N21,2),1) -> 1 | Q21: =IF(LEN('LIGNIN BILBAO'!$N21)>6,RIGHT(LEFT('LIGNIN BILBAO'!$N21,9),1),RIGHT(N21,1)) -> 4 | V21: =VLOOKUP(A21,Z$31:Z$80,1,FALSE) -> 1048 | Z21: 362 | AA21: 11.4815 | AB21: 109.2 | AC21: 362 | AD21: 11.5474 | AE21: 65.9 | AF21: 43.3
A22: 1089 | B22: 11.4655 | C22: 141.5 | D22: =VLOOKUP(A22,'Lignin measurement Plates'!B$72:B$121,1,FALSE) -> 1089 | E22: =VLOOKUP(A22,'Dried samples '!E$2:F$51,2,FALSE) -> 11.5926 | F22: =(E22-B22)*1000 -> 127.1 | G22: =C22-F22 -> 14.4 | H22: =E22-E$64 -> 11.58652 | I22: =(H22-B22)*1000 -> 121.02 | J22: =C22-I22 -> 20.48 | K22: =(J22/C22)*100 -> 14.473498 | L22: =VLOOKUP(A22,'Lignin measurement Plates'!D$182:F$231,2,FALSE) -> 0.085974472 | M22: =L22+K22 -> 14.559473 | N22: =VLOOKUP(A22,Hoja2!A$2:B$872,2,FALSE) -> 65FS2 | O22: =IF(LEN('LIGNIN BILBAO'!N22)>6,RIGHT(LEFT('LIGNIN BILBAO'!N22,11),2),RIGHT((LEFT(N22,4)),2)) -> FS | P22: =IF(LEN('LIGNIN BILBAO'!$N22)>6,LEFT(N22,2),1) -> 1 | Q22: =IF(LEN('LIGNIN BILBAO'!$N22)>6,RIGHT(LEFT('LIGNIN BILBAO'!$N22,9),1),RIGHT(N22,1)) -> 2 | V22: =VLOOKUP(A22,Z$31:Z$80,1,FALSE) -> 1089
A23: 1023 | B23: 11.5091 | C23: 144.4 | D23: =VLOOKUP(A23,'Lignin measurement Plates'!B$72:B$121,1,FALSE) -> 1023 | E23: =VLOOKUP(A23,'Dried samples '!E$2:F$51,2,FALSE) -> 11.6283 | F23: =(E23-B23)*1000 -> 119.2 | G23: =C23-F23 -> 25.2 | H23: =E23-E$64 -> 11.62222 | I23: =(H23-B23)*1000 -> 113.12 | J23: =C23-I23 -> 31.28 | K23: =(J23/C23)*100 -> 21.66205 | L23: =VLOOKUP(A23,'Lignin measurement Plates'!D$182:F$231,2,FALSE) -> 0.096570962 | M23: =L23+K23 -> 21.758621 | N23: =VLOOKUP(A23,Hoja2!A$2:B$872,2,FALSE) -> 31FS2 | O23: =IF(LEN('LIGNIN BILBAO'!N23)>6,RIGHT(LEFT('LIGNIN BILBAO'!N23,11),2),RIGHT((LEFT(N23,4)),2)) -> FS | P23: =IF(LEN('LIGNIN BILBAO'!$N23)>6,LEFT(N23,2),1) -> 1 | Q23: =IF(LEN('LIGNIN BILBAO'!$N23)>6,RIGHT(LEFT('LIGNIN BILBAO'!$N23,9),1),RIGHT(N23,1)) -> 2 | V23: =VLOOKUP(A23,Z$31:Z$80,1,FALSE) -> 1023
A24: 1072 | B24: 11.4125 | C24: 115.7 | D24: =VLOOKUP(A24,'Lignin measurement Plates'!B$72:B$121,1,FALSE) -> 1072 | E24: =VLOOKUP(A24,'Dried samples '!E$2:F$51,2,FALSE) -> 11.5024 | F24: =(E24-B24)*1000 -> 89.9 | G24: =C24-F24 -> 25.8 | H24: =E24-E$64 -> 11.49632 | I24: =(H24-B24)*1000 -> 83.82 | J24: =C24-I24 -> 31.88 | K24: =(J24/C24)*100 -> 27.554019 | L24: =VLOOKUP(A24,'Lignin measurement Plates'!D$182:F$231,2,FALSE) -> 0.083290257 | M24: =L24+K24 -> 27.637309 | N24: =VLOOKUP(A24,Hoja2!A$2:B$872,2,FALSE) -> 33FS4 | O24: =IF(LEN('LIGNIN BILBAO'!N24)>6,RIGHT(LEFT('LIGNIN BILBAO'!N24,11),2),RIGHT((LEFT(N24,4)),2)) -> FS | P24: =IF(LEN('LIGNIN BILBAO'!$N24)>6,LEFT(N24,2),1) -> 1 | Q24: =IF(LEN('LIGNIN BILBAO'!$N24)>6,RIGHT(LEFT('LIGNIN BILBAO'!$N24,9),1),RIGHT(N24,1)) -> 4 | V24: =VLOOKUP(A24,Z$31:Z$80,1,FALSE) -> 1072
A25: 1018 | B25: 11.4642 | C25: 105.1 | D25: =VLOOKUP(A25,'Lignin measurement Plates'!B$72:B$121,1,FALSE) -> 1018 | E25: =VLOOKUP(A25,'Dried samples '!E$2:F$51,2,FALSE) -> 11.5118 | F25: =(E25-B25)*1000 -> 47.6 | G25: =C25-F25 -> 57.5 | H25: =E25-E$64 -> 11.50572 | I25: =(H25-B25)*1000 -> 41.52 | J25: =C25-I25 -> 63.58 | K25: =(J25/C25)*100 -> 60.494767 | L25: =VLOOKUP(A25,'Lignin measurement Plates'!D$182:F$231,2,FALSE) -> 0.097600078 | M25: =L25+K25 -> 60.592367 | N25: =VLOOKUP(A25,Hoja2!A$2:B$872,2,FALSE) -> 15FS4 | O25: =IF(LEN('LIGNIN BILBAO'!N25)>6,RIGHT(LEFT('LIGNIN BILBAO'!N25,11),2),RIGHT((LEFT(N25,4)),2)) -> FS | P25: =IF(LEN('LIGNIN BILBAO'!$N25)>6,LEFT(N25,2),1) -> 1 | Q25: =IF(LEN('LIGNIN BILBAO'!$N25)>6,RIGHT(LEFT('LIGNIN BILBAO'!$N25,9),1),RIGHT(N25,1)) -> 4 | V25: =VLOOKUP(A25,Z$31:Z$80,1,FALSE) -> 1018
A26: 1032 | B26: 11.4968 | C26: 151.3 | D26: =VLOOKUP(A26,'Lignin measurement Plates'!B$72:B$121,1,FALSE) -> 1032 | E26: =VLOOKUP(A26,'Dried samples '!E$2:F$51,2,FALSE) -> 11.6089 | F26: =(E26-B26)*1000 -> 112.1 | G26: =C26-F26 -> 39.2 | H26: =E26-E$64 -> 11.60282 | I26: =(H26-B26)*1000 -> 106.02 | J26: =C26-I26 -> 45.28 | K26: =(J26/C26)*100 -> 29.927297 | L26: =VLOOKUP(A26,'Lignin measurement Plates'!D$182:F$231,2,FALSE) -> 0.016680606 | M26: =L26+K26 -> 29.943977 | N26: =VLOOKUP(A26,Hoja2!A$2:B$872,2,FALSE) -> 35AA2 | O26: =IF(LEN('LIGNIN BILBAO'!N26)>6,RIGHT(LEFT('LIGNIN BILBAO'!N26,11),2),RIGHT((LEFT(N26,4)),2)) -> AA | P26: =IF(LEN('LIGNIN BILBAO'!$N26)>6,LEFT(N26,2),1) -> 1 | Q26: =IF(LEN('LIGNIN BILBAO'!$N26)>6,RIGHT(LEFT('LIGNIN BILBAO'!$N26,9),1),RIGHT(N26,1)) -> 2 | V26: =VLOOKUP(A26,Z$31:Z$80,1,FALSE) -> 1032
A27: 1007 | B27: 11.4045 | C27: 107.3 | D27: =VLOOKUP(A27,'Lignin measurement Plates'!B$72:B$121,1,FALSE) -> 1007 | E27: =VLOOKUP(A27,'Dried samples '!E$2:F$51,2,FALSE) -> 11.5607 | F27: =(E27-B27)*1000 -> 156.2 | G27: =C27-F27 -> -48.9 | H27: =E27-E$64 -> 11.55462 | I27: =(H27-B27)*1000 -> 150.12 | J27: =C27-I27 -> -42.82 | K27: =(J27/C27)*100 -> -39.906803 | L27: =VLOOKUP(A27,'Lignin measurement Plates'!D$182:F$231,2,FALSE) -> 0.031008792 | N27: =VLOOKUP(A27,Hoja2!A$2:B$872,2,FALSE) -> 12AA1 | O27: =IF(LEN('LIGNIN BILBAO'!N27)>6,RIGHT(LEFT('LIGNIN BILBAO'!N27,11),2),RIGHT((LEFT(N27,4)),2)) -> AA | P27: =IF(LEN('LIGNIN BILBAO'!$N27)>6,LEFT(N27,2),1) -> 1 | Q27: =IF(LEN('LIGNIN BILBAO'!$N27)>6,RIGHT(LEFT('LIGNIN BILBAO'!$N27,9),1),RIGHT(N27,1)) -> 1 | V27: =VLOOKUP(A27,Z$31:Z$80,1,FALSE) -> 1007
A28: 1055 | B28: 11.4835 | C28: 116.4 | D28: =VLOOKUP(A28,'Lignin measurement Plates'!B$72:B$121,1,FALSE) -> 1055 | E28: =VLOOKUP(A28,'Dried samples '!E$2:F$51,2,FALSE) -> 11.5633 | F28: =(E28-B28)*1000 -> 79.8 | G28: =C28-F28 -> 36.6 | H28: =E28-E$64 -> 11.55722 | I28: =(H28-B28)*1000 -> 73.72 | J28: =C28-I28 -> 42.68 | K28: =(J28/C28)*100 -> 36.666667 | L28: =VLOOKUP(A28,'Lignin measurement Plates'!D$182:F$231,2,FALSE) -> 0.022698262 | M28: =L28+K28 -> 36.689365 | N28: =VLOOKUP(A28,Hoja2!A$2:B$872,2,FALSE) -> 14AA1 | O28: =IF(LEN('LIGNIN BILBAO'!N28)>6,RIGHT(LEFT('LIGNIN BILBAO'!N28,11),2),RIGHT((LEFT(N28,4)),2)) -> AA | P28: =IF(LEN('LIGNIN BILBAO'!$N28)>6,LEFT(N28,2),1) -> 1 | Q28: =IF(LEN('LIGNIN BILBAO'!$N28)>6,RIGHT(LEFT('LIGNIN BILBAO'!$N28,9),1),RIGHT(N28,1)) -> 1 | V28: =VLOOKUP(A28,Z$31:Z$80,1,FALSE) -> 1055
A29: 1039 | B29: 11.4035 | C29: 122.1 | D29: =VLOOKUP(A29,'Lignin measurement Plates'!B$72:B$121,1,FALSE) -> 1039 | E29: =VLOOKUP(A29,'Dried samples '!E$2:F$51,2,FALSE) -> 11.4888 | F29: =(E29-B29)*1000 -> 85.3 | G29: =C29-F29 -> 36.8 | H29: =E29-E$64 -> 11.48272 | I29: =(H29-B29)*1000 -> 79.22 | J29: =C29-I29 -> 42.88 | K29: =(J29/C29)*100 -> 35.118755 | L29: =VLOOKUP(A29,'Lignin measurement Plates'!D$182:F$231,2,FALSE) -> 0.032942405 | M29: =L29+K29 -> 35.151698 | N29: =VLOOKUP(A29,Hoja2!A$2:B$872,2,FALSE) -> 63AA4 | O29: =IF(LEN('LIGNIN BILBAO'!N29)>6,RIGHT(LEFT('LIGNIN BILBAO'!N29,11),2),RIGHT((LEFT(N29,4)),2)) -> AA | P29: =IF(LEN('LIGNIN BILBAO'!$N29)>6,LEFT(N29,2),1) -> 1 | Q29: =IF(LEN('LIGNIN BILBAO'!$N29)>6,RIGHT(LEFT('LIGNIN BILBAO'!$N29,9),1),RIGHT(N29,1)) -> 4 | V29: =VLOOKUP(A29,Z$31:Z$80,1,FALSE) -> 1039
A30: 1019 | B30: 11.5084 | C30: 133 | D30: =VLOOKUP(A30,'Lignin measurement Plates'!B$72:B$121,1,FALSE) -> 1019 | E30: =VLOOKUP(A30,'Dried samples '!E$2:F$51,2,FALSE) -> 11.758 | F30: =(E30-B30)*1000 -> 249.6 | G30: =C30-F30 -> -116.6 | H30: =E30-E$64 -> 11.75192 | I30: =(H30-B30)*1000 -> 243.52 | J30: =C30-I30 -> -110.52 | K30: =(J30/C30)*100 -> -83.097744 | L30: =VLOOKUP(A30,'Lignin measurement Plates'!D$182:F$231,2,FALSE) -> 0.023460263 | N30: =VLOOKUP(A30,Hoja2!A$2:B$872,2,FALSE) -> 31AA1 | O30: =IF(LEN('LIGNIN BILBAO'!N30)>6,RIGHT(LEFT('LIGNIN BILBAO'!N30,11),2),RIGHT((LEFT(N30,4)),2)) -> AA | P30: =IF(LEN('LIGNIN BILBAO'!$N30)>6,LEFT(N30,2),1) -> 1 | Q30: =IF(LEN('LIGNIN BILBAO'!$N30)>6,RIGHT(LEFT('LIGNIN BILBAO'!$N30,9),1),RIGHT(N30,1)) -> 1 | V30: =VLOOKUP(A30,Z$31:Z$80,1,FALSE) -> 1019
A31: 1063 | B31: 11.4651 | C31: 109.6 | D31: =VLOOKUP(A31,'Lignin measurement Plates'!B$72:B$121,1,FALSE) -> 1063 | E31: =VLOOKUP(A31,'Dried samples '!E$2:F$51,2,FALSE) -> 11.6638 | F31: =(E31-B31)*1000 -> 198.7 | G31: =C31-F31 -> -89.1 | H31: =E31-E$64 -> 11.65772 | I31: =(H31-B31)*1000 -> 192.62 | J31: =C31-I31 -> -83.02 | K31: =(J31/C31)*100 -> -75.748175 | L31: =VLOOKUP(A31,'Lignin measurement Plates'!D$182:F$231,2,FALSE) -> 0.031977157 | N31: =VLOOKUP(A31,Hoja2!A$2:B$872,2,FALSE) -> 32AA4 | O31: =IF(LEN('LIGNIN BILBAO'!N31)>6,RIGHT(LEFT('LIGNIN BILBAO'!N31,11),2),RIGHT((LEFT(N31,4)),2)) -> AA | P31: =IF(LEN('LIGNIN BILBAO'!$N31)>6,LEFT(N31,2),1) -> 1 | Q31: =IF(LEN('LIGNIN BILBAO'!$N31)>6,RIGHT(LEFT('LIGNIN BILBAO'!$N31,9),1),RIGHT(N31,1)) -> 4 | V31: =VLOOKUP(A31,Z$31:Z$80,1,FALSE) -> #N/A | X31: FALTA 1063! | Y31: =VLOOKUP(AC31,A2:A51,1,FALSE) -> #N/A | Z31: 1040 | AA31: =VLOOKUP(AC31,Hoja2!A$2:B$872,2,FALSE) -> 35FS4 | AC31: 1036
A32: 1086 | B32: 11.4947 | C32: 118.4 | D32: =VLOOKUP(A32,'Lignin measurement Plates'!B$72:B$121,1,FALSE) -> 1086 | E32: =VLOOKUP(A32,'Dried samples '!E$2:F$51,2,FALSE) -> 11.6021 | F32: =(E32-B32)*1000 -> 107.4 | G32: =C32-F32 -> 11 | H32: =E32-E$64 -> 11.59602 | I32: =(H32-B32)*1000 -> 101.32 | J32: =C32-I32 -> 17.08 | K32: =(J32/C32)*100 -> 14.425676 | L32: =VLOOKUP(A32,'Lignin measurement Plates'!D$182:F$231,2,FALSE) -> 0.015279008 | M32: =L32+K32 -> 14.440955 | N32: =VLOOKUP(A32,Hoja2!A$2:B$872,2,FALSE) -> 65AA2 | O32: =IF(LEN('LIGNIN BILBAO'!N32)>6,RIGHT(LEFT('LIGNIN BILBAO'!N32,11),2),RIGHT((LEFT(N32,4)),2)) -> AA | P32: =IF(LEN('LIGNIN BILBAO'!$N32)>6,LEFT(N32,2),1) -> 1 | Q32: =IF(LEN('LIGNIN BILBAO'!$N32)>6,RIGHT(LEFT('LIGNIN BILBAO'!$N32,9),1),RIGHT(N32,1)) -> 2 | V32: =VLOOKUP(A32,Z$31:Z$80,1,FALSE) -> 1086 | Z32: 1018 | AA32: =VLOOKUP(Z32,Hoja2!A$2:B$872,2,FALSE) -> 15FS4
A33: 1025 | B33: 11.4914 | C33: 105.1 | D33: =VLOOKUP(A33,'Lignin measurement Plates'!B$72:B$121,1,FALSE) -> 1025 | E33: =VLOOKUP(A33,'Dried samples '!E$2:F$51,2,FALSE) -> 11.6068 | F33: =(E33-B33)*1000 -> 115.4 | G33: =C33-F33 -> -10.3 | H33: =E33-E$64 -> 11.60072 | I33: =(H33-B33)*1000 -> 109.32 | J33: =C33-I33 -> -4.22 | K33: =(J33/C33)*100 -> -4.0152236 | L33: =VLOOKUP(A33,'Lignin measurement Plates'!D$182:F$231,2,FALSE) -> 0.020542448 | N33: =VLOOKUP(A33,Hoja2!A$2:B$872,2,FALSE) -> 34AA1 | O33: =IF(LEN('LIGNIN BILBAO'!N33)>6,RIGHT(LEFT('LIGNIN BILBAO'!N33,11),2),RIGHT((LEFT(N33,4)),2)) -> AA | P33: =IF(LEN('LIGNIN BILBAO'!$N33)>6,LEFT(N33,2),1) -> 1 | Q33: =IF(LEN('LIGNIN BILBAO'!$N33)>6,RIGHT(LEFT('LIGNIN BILBAO'!$N33,9),1),RIGHT(N33,1)) -> 1 | V33: =VLOOKUP(A33,Z$31:Z$80,1,FALSE) -> 1025 | Z33: 125 | AA33: =VLOOKUP(Z33,Hoja2!A$2:B$872,2,FALSE) -> 25-P1S5C2FS
A34: 1027 | B34: 11.416 | C34: 116.3 | D34: =VLOOKUP(A34,'Lignin measurement Plates'!B$72:B$121,1,FALSE) -> 1027 | E34: =VLOOKUP(A34,'Dried samples '!E$2:F$51,2,FALSE) -> 11.5128 | F34: =(E34-B34)*1000 -> 96.8 | G34: =C34-F34 -> 19.5 | H34: =E34-E$64 -> 11.50672 | I34: =(H34-B34)*1000 -> 90.72 | J34: =C34-I34 -> 25.58 | K34: =(J34/C34)*100 -> 21.994841 | L34: =VLOOKUP(A34,'Lignin measurement Plates'!D$182:F$231,2,FALSE) -> 0.02543035 | M34: =L34+K34 -> 22.020271 | N34: =VLOOKUP(A34,Hoja2!A$2:B$872,2,FALSE) -> 34AA4 | O34: =IF(LEN('LIGNIN BILBAO'!N34)>6,RIGHT(LEFT('LIGNIN BILBAO'!N34,11),2),RIGHT((LEFT(N34,4)),2)) -> AA | P34: =IF(LEN('LIGNIN BILBAO'!$N34)>6,LEFT(N34,2),1) -> 1 | Q34: =IF(LEN('LIGNIN BILBAO'!$N34)>6,RIGHT(LEFT('LIGNIN BILBAO'!$N34,9),1),RIGHT(N34,1)) -> 4 | V34: =VLOOKUP(A34,Z$31:Z$80,1,FALSE) -> 1027 | Z34: 396 | AA34: =VLOOKUP(Z34,Hoja2!A$2:B$872,2,FALSE) -> 25-P6S5C1AA
A35: 1003 | B35: 11.4923 | C35: 106.7 | D35: =VLOOKUP(A35,'Lignin measurement Plates'!B$72:B$121,1,FALSE) -> 1003 | E35: =VLOOKUP(A35,'Dried samples '!E$2:F$51,2,FALSE) -> 11.6046 | F35: =(E35-B35)*1000 -> 112.3 | G35: =C35-F35 -> -5.6 | H35: =E35-E$64 -> 11.59852 | I35: =(H35-B35)*1000 -> 106.22 | J35: =C35-I35 -> 0.48 | K35: =(J35/C35)*100 -> 0.44985942 | L35: =VLOOKUP(A35,'Lignin measurement Plates'!D$182:F$231,2,FALSE) -> 0.029982033 | M35: =L35+K35 -> 0.47984145 | N35: =VLOOKUP(A35,Hoja2!A$2:B$872,2,FALSE) -> 11AA4 | O35: =IF(LEN('LIGNIN BILBAO'!N35)>6,RIGHT(LEFT('LIGNIN BILBAO'!N35,11),2),RIGHT((LEFT(N35,4)),2)) -> AA | P35: =IF(LEN('LIGNIN BILBAO'!$N35)>6,LEFT(N35,2),1) -> 1 | Q35: =IF(LEN('LIGNIN BILBAO'!$N35)>6,RIGHT(LEFT('LIGNIN BILBAO'!$N35,9),1),RIGHT(N35,1)) -> 4 | V35: =VLOOKUP(A35,Z$31:Z$80,1,FALSE) -> 1003 | Z35: 157 | AA35: =VLOOKUP(Z35,Hoja2!A$2:B$872,2,FALSE) -> 10-P3S2C4FS
A36: 40 | B36: 11.4656 | C36: 103.1 | D36: =VLOOKUP(A36,'Lignin measurement Plates'!B$72:B$121,1,FALSE) -> 40 | E36: =VLOOKUP(A36,'Dried samples '!E$2:F$51,2,FALSE) -> 11.6922 | F36: =(E36-B36)*1000 -> 226.6 | G36: =C36-F36 -> -123.5 | H36: =E36-E$64 -> 11.68612 | I36: =(H36-B36)*1000 -> 220.52 | J36: =C36-I36 -> -117.42 | K36: =(J36/C36)*100 -> -113.88943 | L36: =VLOOKUP(A36,'Lignin measurement Plates'!D$182:F$231,2,FALSE) -> 0.10523063 | N36: =VLOOKUP(A36,Hoja2!A$2:B$872,2,FALSE) -> 25-P1S2C1FS | O36: =IF(LEN('LIGNIN BILBAO'!N36)>6,RIGHT(LEFT('LIGNIN BILBAO'!N36,11),2),RIGHT((LEFT(N36,4)),2)) -> FS | P36: =IF(LEN('LIGNIN BILBAO'!$N36)>6,LEFT(N36,2),1) -> 25 | Q36: =IF(LEN('LIGNIN BILBAO'!$N36)>6,RIGHT(LEFT('LIGNIN BILBAO'!$N36,9),1),RIGHT(N36,1)) -> 1 | V36: =VLOOKUP(A36,Z$31:Z$80,1,FALSE) -> 40 | Z36: 1032 | AA36: =VLOOKUP(Z36,Hoja2!A$2:B$872,2,FALSE) -> 35AA2
A37: 149 | B37: 11.5657 | C37: 103.6 | D37: =VLOOKUP(A37,'Lignin measurement Plates'!B$72:B$121,1,FALSE) -> 149 | E37: =VLOOKUP(A37,'Dried samples '!E$2:F$51,2,FALSE) -> 11.7691 | F37: =(E37-B37)*1000 -> 203.4 | G37: =C37-F37 -> -99.8 | H37: =E37-E$64 -> 11.76302 | I37: =(H37-B37)*1000 -> 197.32 | J37: =C37-I37 -> -93.72 | K37: =(J37/C37)*100 -> -90.46332 | L37: =VLOOKUP(A37,'Lignin measurement Plates'!D$182:F$231,2,FALSE) -> 0.07679352 | N37: =VLOOKUP(A37,Hoja2!A$2:B$872,2,FALSE) -> 25-P3S2C1FS | O37: =IF(LEN('LIGNIN BILBAO'!N37)>6,RIGHT(LEFT('LIGNIN BILBAO'!N37,11),2),RIGHT((LEFT(N37,4)),2)) -> FS | P37: =IF(LEN('LIGNIN BILBAO'!$N37)>6,LEFT(N37,2),1) -> 25 | Q37: =IF(LEN('LIGNIN BILBAO'!$N37)>6,RIGHT(LEFT('LIGNIN BILBAO'!$N37,9),1),RIGHT(N37,1)) -> 1 | V37: =VLOOKUP(A37,Z$31:Z$80,1,FALSE) -> 149 | Z37: 142 | AA37: =VLOOKUP(Z37,Hoja2!A$2:B$872,2,FALSE) -> 10-P3S1C4AA
A38: 150 | B38: 11.5094 | C38: 105.9 | D38: =VLOOKUP(A38,'Lignin measurement Plates'!B$72:B$121,1,FALSE) -> 150 | E38: =VLOOKUP(A38,'Dried samples '!E$2:F$51,2,FALSE) -> 11.6914 | F38: =(E38-B38)*1000 -> 182 | G38: =C38-F38 -> -76.1 | H38: =E38-E$64 -> 11.68532 | I38: =(H38-B38)*1000 -> 175.92 | J38: =C38-I38 -> -70.02 | K38: =(J38/C38)*100 -> -66.11898 | L38: =VLOOKUP(A38,'Lignin measurement Plates'!D$182:F$231,2,FALSE) -> 0.09583876 | N38: =VLOOKUP(A38,Hoja2!A$2:B$872,2,FALSE) -> 25-P3S2C2FS | O38: =IF(LEN('LIGNIN BILBAO'!N38)>6,RIGHT(LEFT('LIGNIN BILBAO'!N38,11),2),RIGHT((LEFT(N38,4)),2)) -> FS | P38: =IF(LEN('LIGNIN BILBAO'!$N38)>6,LEFT(N38,2),1) -> 25 | Q38: =IF(LEN('LIGNIN BILBAO'!$N38)>6,RIGHT(LEFT('LIGNIN BILBAO'!$N38,9),1),RIGHT(N38,1)) -> 2 | V38: =VLOOKUP(A38,Z$31:Z$80,1,FALSE) -> 150 | Z38: 84 | AA38: =VLOOKUP(Z38,Hoja2!A$2:B$872,2,FALSE) -> 10-P1S3C4FS
A39: 382 | B39: 11.4142 | C39: 117.4 | D39: =VLOOKUP(A39,'Lignin measurement Plates'!B$72:B$121,1,FALSE) -> 382 | E39: =VLOOKUP(A39,'Dried samples '!E$2:F$51,2,FALSE) -> 11.6054 | F39: =(E39-B39)*1000 -> 191.2 | G39: =C39-F39 -> -73.8 | H39: =E39-E$64 -> 11.59932 | I39: =(H39-B39)*1000 -> 185.12 | J39: =C39-I39 -> -67.72 | K39: =(J39/C39)*100 -> -57.683135 | L39: =VLOOKUP(A39,'Lignin measurement Plates'!D$182:F$231,2,FALSE) -> 0.085946965 | N39: =VLOOKUP(A39,Hoja2!A$2:B$872,2,FALSE) -> 25-P6S4C2FS | O39: =IF(LEN('LIGNIN BILBAO'!N39)>6,RIGHT(LEFT('LIGNIN BILBAO'!N39,11),2),RIGHT((LEFT(N39,4)),2)) -> FS | P39: =IF(LEN('LIGNIN BILBAO'!$N39)>6,LEFT(N39,2),1) -> 25 | Q39: =IF(LEN('LIGNIN BILBAO'!$N39)>6,RIGHT(LEFT('LIGNIN BILBAO'!$N39,9),1),RIGHT(N39,1)) -> 2 | V39: =VLOOKUP(A39,Z$31:Z$80,1,FALSE) -> #N/A | Z39: 7 | AA39: =VLOOKUP(Z39,Hoja2!A$2:B$872,2,FALSE) -> 10-P1S1C1AA
A40: 125 | B40: 11.4828 | C40: 105.5 | D40: =VLOOKUP(A40,'Lignin measurement Plates'!B$72:B$121,1,FALSE) -> 125 | E40: =VLOOKUP(A40,'Dried samples '!E$2:F$51,2,FALSE) -> 11.6208 | F40: =(E40-B40)*1000 -> 138 | G40: =C40-F40 -> -32.5 | H40: =E40-E$64 -> 11.61472 | I40: =(H40-B40)*1000 -> 131.92 | J40: =C40-I40 -> -26.42 | K40: =(J40/C40)*100 -> -25.042654 | L40: =VLOOKUP(A40,'Lignin measurement Plates'!D$182:F$231,2,FALSE) -> 0.10031373 | N40: =VLOOKUP(A40,Hoja2!A$2:B$872,2,FALSE) -> 25-P1S5C2FS | O40: =IF(LEN('LIGNIN BILBAO'!N40)>6,RIGHT(LEFT('LIGNIN BILBAO'!N40,11),2),RIGHT((LEFT(N40,4)),2)) -> FS | P40: =IF(LEN('LIGNIN BILBAO'!$N40)>6,LEFT(N40,2),1) -> 25 | Q40: =IF(LEN('LIGNIN BILBAO'!$N40)>6,RIGHT(LEFT('LIGNIN BILBAO'!$N40,9),1),RIGHT(N40,1)) -> 2 | V40: =VLOOKUP(A40,Z$31:Z$80,1,FALSE) -> 125 | Z40: 120 | AA40: =VLOOKUP(Z40,Hoja2!A$2:B$872,2,FALSE) -> 10-P1S4C4FS
...

Sheet Counting for FITR
B4: AA | C4: 1 | D4: 10 | E4: 25 | F4: Diam | I4: AA | J4: 1 | K4: 10 | L4: 25 | M4: Diam
B5: 1 | C5: 4 | D5: 6 | E5: 4 | I5: 1 | J5: =5-C5 -> 1 | K5: 0 | L5: =5-E5 -> 1 | O5: AA
B6: 2 | C6: 2 | D6: 2 | E6: 2 | I6: 2 | J6: =5-C6 -> 3 | K6: =5-D6 -> 3 | L6: =5-E6 -> 3 | P6: 1 | Q6: 1(1) | R6: 1079
B7: 4 | C7: 4 | D7: 1 | E7: 5 | I7: 4 | J7: =5-C7 -> 1 | K7: =5-D7 -> 4 | L7: =5-E7 -> 0 | Q7: 2(3) | R7: 1062 | S7: 1050 | T7: 1020
B8: Class | I8: Class | Q8: 4(1) | R8: 1021
P9: 10
Q10: =_xlfn.CONCAT(1,"(",K5,")") -> 1(0)
B11: FS | C11: 1 | D11: 10 | E11: 25 | I11: FS | J11: 1 | K11: 10 | L11: 25 | Q11: =_xlfn.CONCAT(2,"(",K6,")") -> 2(3) | R11: 333 | S11: 386 | T11: 119
B12: 1 | C12: 1 | D12: 4 | E12: 2 | I12: 1 | J12: =5-C12 -> 4 | K12: =5-D12 -> 1 | L12: =5-E12 -> 3 | Q12: =_xlfn.CONCAT(4,"(",K7,")") -> 4(4) | R12: 117 | S12: 406 | T12: 371 | U12: 81
B13: 2 | C13: 3 | D13: 0 | E13: 4 | I13: 2 | J13: =5-C13 -> 2 | K13: =5-D13 -> 5 | L13: =5-E13 -> 1 | P13: 25
B14: 4 | C14: 3 | D14: 3 | E14: 0 | I14: 4 | J14: =5-C14 -> 2 | K14: =5-D14 -> 2 | L14: =5-E14 -> 5 | Q14: 1(1) | R14: 73
Q15: 2(3) | R15: 74 | S15: 135 | T15: 159
Q16: 4(0)
B19: SEARCH | L19: =SUM(J5:L7,J12:L14) -> 41 | O19: FS
B20: Code | P20: 1 | Q20: 1(4) | R20: 1022 | S20: 1040 | T20: 1058 | U20: 1034
I21: 1033 | Q21: 2(2) | R21: 1029 | S21: 1065
A22: 1079 | I22: =VLOOKUP(I21,Hoja2!A2:B872,2,FALSE) -> 35AA4 | Q22: 4(2) | R22: 1090 | S22: 1012
A23: 1062 | P23: 10
A24: 1021 | Q24: 1(1) | R24: 337
A25: 333 | Q25: 2(5) | R25: 339 | S25: 11 | T25: 180 | U25: 47 | V25: 131
A26: 117 | Q26: 4(2) | R26: 341 | S26: 145
A27: 73 | P27: 25
A28: 74 | Q28: 1(3) | R28: 185 | S28: 112 | T28: 124
A29: 1022 | Q29: 2(1) | R29: 346
A30: 1029 | Q30: 4(5) | R30: 151 | S30: 42 | T30: 144 | U30: 383 | V30: 329
A31: 1090
A32: 337
A33: 339
A34: 341
A35: 185
A36: 346
A37: 151
F62: =COUNT(F26:F59) -> 0

Sheet pH measurement
A1: Abies
A2: 1 | D2: 10 | G2: 25
A3: 1 | B3: 2 | C3: 4 | D3: 1 | E3: 2 | F3: 4 | G3: 1 | H3: 2 | I3: 4
A4: 1073 | B4: 1002 | C4: 1045 | D4: 43 | E4: 387 | F4: 353 | G4: 121 | H4: 325 | I4: 136
A5: 1043 | B5: 1044 | C5: 1009 | D5: 367 | E5: 165 | F5: 389 | G5: 363 | H5: 2 | I5: 123
A6: 1031 | B6: 1074 | C6: 1051 | D6: 188 | E6: 177 | F6: 388 | G6: 360 | H6: 183 | I6: 148
A7: 1001 | B7: 1038 | C7: 1075 | D7: 402 | E7: 80 | F7: 190 | G7: 378 | H7: 343 | I7: 172
A8: 1085 | B8: 1014 | C8: 1033 | D8: 384 | E8: 128 | F8: 166 | G8: 342 | H8: 379 | I8: 398
A11: Fagus
A12: 1 | D12: 10 | G12: 25
A13: 1 | B13: 2 | C13: 4 | D13: 1 | E13: 2 | F13: 4 | G13: 1 | H13: 2 | I13: 4
A14: 1052 | B14: 1083 | C14: 1006 | D14: 354 | E14: 192 | F14: 169 | G14: 381 | H14: 400 | I14: 114
A15: 1088 | B15: 1071 | C15: 1036 | D15: 143 | E15: 411 | F15: 132 | G15: 345 | H15: 328 | I15: 6
A16: 1046 | B16: 1005 | C16: 1084 | D16: 390 | E16: 392 | F16: 412 | G16: 161 | H16: 41 | I16: 175
A17: 1004 | B17: 1077 | C17: 1078 | D17: 372 | E17: 338 | F17: 395 | G17: 4 | H17: 138 | I17: 139
A18: 1010 | B18: 1011 | C18: 1030 | D18: 391 | E18: 375 | F18: 193 | G18: 381 | H18: 77 | I18: 78
A20: VRIJA Code | B20: DeWood Code | C20: Code | D20: Species | E20: Diameter | F20: Class | G20: pH | L20: VRIJA Code | M20: DeWood Code | N20: Code | O20: Species | P20: Diameter | Q20: Class | R20: pH
A21: 1 | B21: Birch Leaf | D21: Birch | G21: 4.95 | L21: 65 | M21: 1043 | N21: 64AA1 | O21: AA | P21: 1 | Q21: 1
A22: 2 | B22: 1073 | C22: =VLOOKUP(B22,Hoja2!A$2:B$872,2,FALSE) -> 61AA1 | D22: =IF(LEN('pH measurement'!C22)>6,RIGHT(LEFT('pH measurement'!C22,11),2),RIGHT((LEFT(C22,4)),2)) -> AA | E22: =IF(LEN('pH measurement'!$C22)>6,LEFT(C22,2),1) -> 1 | F22: =IF(LEN('pH measurement'!$C22)>6,RIGHT(LEFT('pH measurement'!$C22,9),1),RIGHT(C22,1)) -> 1 | G22: 4.56 | L22: 67 | M22: 1031 | N22: 35AA1 | O22: AA | P22: 1 | Q22: 1
A23: 3 | B23: 172 | C23: =VLOOKUP(B23,Hoja2!A$2:B$872,2,FALSE) -> 25-P3S4C4AA | D23: =IF(LEN('pH measurement'!C23)>6,RIGHT(LEFT('pH measurement'!C23,11),2),RIGHT((LEFT(C23,4)),2)) -> AA | E23: =IF(LEN('pH measurement'!$C23)>6,LEFT(C23,2),1) -> 25 | F23: =IF(LEN('pH measurement'!$C23)>6,RIGHT(LEFT('pH measurement'!$C23,9),1),RIGHT(C23,1)) -> 4 | G23: 3.8 | L23: 66 | M23: 188 | N23: 10-P3S5C1AA | O23: AA | P23: 10 | Q23: 1
A24: 4 | B24: 343 | C24: =VLOOKUP(B24,Hoja2!A$2:B$872,2,FALSE) -> 25-P6S2C2AA | D24: =IF(LEN('pH measurement'!C24)>6,RIGHT(LEFT('pH measurement'!C24,11),2),RIGHT((LEFT(C24,4)),2)) -> AA | E24: =IF(LEN('pH measurement'!$C24)>6,LEFT(C24,2),1) -> 25 | F24: =IF(LEN('pH measurement'!$C24)>6,RIGHT(LEFT('pH measurement'!$C24,9),1),RIGHT(C24,1)) -> 2 | G24: 4.88 | L24: 75 | M24: 43 | N24: 10-P1S2C1AA | O24: AA | P24: 10 | Q24: 1
A25: 5 | B25: 77 | C25: =VLOOKUP(B25,Hoja2!A$2:B$872,2,FALSE) -> 25-P1S3C2FS | D25: =IF(LEN('pH measurement'!C25)>6,RIGHT(LEFT('pH measurement'!C25,11),2),RIGHT((LEFT(C25,4)),2)) -> FS | E25: =IF(LEN('pH measurement'!$C25)>6,LEFT(C25,2),1) -> 25 | F25: =IF(LEN('pH measurement'!$C25)>6,RIGHT(LEFT('pH measurement'!$C25,9),1),RIGHT(C25,1)) -> 2 | G25: 5.63 | L25: 81 | M25: 367 | N25: 10-P6S3C1AA -b | O25: AA | P25: 10 | Q25: 1
A26: 6 | B26: 398 | C26: =VLOOKUP(B26,Hoja2!A$2:B$872,2,FALSE) -> 25-P6S5C4AA | D26: =IF(LEN('pH measurement'!C26)>6,RIGHT(LEFT('pH measurement'!C26,11),2),RIGHT((LEFT(C26,4)),2)) -> AA | E26: =IF(LEN('pH measurement'!$C26)>6,LEFT(C26,2),1) -> 25 | F26: =IF(LEN('pH measurement'!$C26)>6,RIGHT(LEFT('pH measurement'!$C26,9),1),RIGHT(C26,1)) -> 4 | G26: 3.7 | L26: 63 | M26: 390 | N26: 10-P6S4C1FS | O26: FS | P26: 10 | Q26: 1
A27: 7 | B27: 1014 | C27: =VLOOKUP(B27,Hoja2!A$2:B$872,2,FALSE) -> 15AA2 | D27: =IF(LEN('pH measurement'!C27)>6,RIGHT(LEFT('pH measurement'!C27,11),2),RIGHT((LEFT(C27,4)),2)) -> AA | E27: =IF(LEN('pH measurement'!$C27)>6,LEFT(C27,2),1) -> 1 | F27: =IF(LEN('pH measurement'!$C27)>6,RIGHT(LEFT('pH measurement'!$C27,9),1),RIGHT(C27,1)) -> 2 | G27: 5.39 | L27: 70 | M27: 372 | N27: 10-P6S3C1FS | O27: FS | P27: 10 | Q27: 1
A28: 8 | B28: 379 | C28: =VLOOKUP(B28,Hoja2!A$2:B$872,2,FALSE) -> 25-P6S4C2AA | D28: =IF(LEN('pH measurement'!C28)>6,RIGHT(LEFT('pH measurement'!C28,11),2),RIGHT((LEFT(C28,4)),2)) -> AA | E28: =IF(LEN('pH measurement'!$C28)>6,LEFT(C28,2),1) -> 25 | F28: =IF(LEN('pH measurement'!$C28)>6,RIGHT(LEFT('pH measurement'!$C28,9),1),RIGHT(C28,1)) -> 2 | G28: 5.62 | L28: 83 | M28: 354 | N28: 10-P6S2C1FS | O28: FS | P28: 10 | Q28: 1
A29: 9 | B29: 381 | C29: =VLOOKUP(B29,Hoja2!A$2:B$872,2,FALSE) -> 25-P6S4C1FS | D29: =IF(LEN('pH measurement'!C29)>6,RIGHT(LEFT('pH measurement'!C29,11),2),RIGHT((LEFT(C29,4)),2)) -> FS | E29: =IF(LEN('pH measurement'!$C29)>6,LEFT(C29,2),1) -> 25 | F29: =IF(LEN('pH measurement'!$C29)>6,RIGHT(LEFT('pH measurement'!$C29,9),1),RIGHT(C29,1)) -> 1 | G29: 5.55 | L29: 88 | M29: 143 | N29: 10-P3S1C1FS | O29: FS | P29: 10 | Q29: 1
A30: 10 | B30: 1071 | C30: =VLOOKUP(B30,Hoja2!A$2:B$872,2,FALSE) -> 33FS2 | D30: =IF(LEN('pH measurement'!C30)>6,RIGHT(LEFT('pH measurement'!C30,11),2),RIGHT((LEFT(C30,4)),2)) -> FS | E30: =IF(LEN('pH measurement'!$C30)>6,LEFT(C30,2),1) -> 1 | F30: =IF(LEN('pH measurement'!$C30)>6,RIGHT(LEFT('pH measurement'!$C30,9),1),RIGHT(C30,1)) -> 2 | G30: 5.86 | L30: 74 | M30: 121 | N30: 25-P1S5C1AA | O30: AA | P30: 25 | Q30: 1
A31: 11 | B31: 1033 | C31: =VLOOKUP(B31,Hoja2!A$2:B$872,2,FALSE) -> 35AA4 | D31: =IF(LEN('pH measurement'!C31)>6,RIGHT(LEFT('pH measurement'!C31,11),2),RIGHT((LEFT(C31,4)),2)) -> AA | E31: =IF(LEN('pH measurement'!$C31)>6,LEFT(C31,2),1) -> 1 | F31: =IF(LEN('pH measurement'!$C31)>6,RIGHT(LEFT('pH measurement'!$C31,9),1),RIGHT(C31,1)) -> 4 | G31: 4.9 | L31: 53 | M31: 345 | N31: 25-P6S2C1FS | O31: FS | P31: 25 | Q31: 1
A32: 12 | B32: 342 | C32: =VLOOKUP(B32,Hoja2!A$2:B$872,2,FALSE) -> 25-P6S2C1AA | D32: =IF(LEN('pH measurement'!C32)>6,RIGHT(LEFT('pH measurement'!C32,11),2),RIGHT((LEFT(C32,4)),2)) -> AA | E32: =IF(LEN('pH measurement'!$C32)>6,LEFT(C32,2),1) -> 25 | F32: =IF(LEN('pH measurement'!$C32)>6,RIGHT(LEFT('pH measurement'!$C32,9),1),RIGHT(C32,1)) -> 1 | G32: 5.85 | L32: 54 | M32: 161 | N32: 25-P3S3C1FS | O32: FS | P32: 25 | Q32: 1
A33: 13 | B33: 1004 | C33: =VLOOKUP(B33,Hoja2!A$2:B$872,2,FALSE) -> 11FS1 | D33: =IF(LEN('pH measurement'!C33)>6,RIGHT(LEFT('pH measurement'!C33,11),2),RIGHT((LEFT(C33,4)),2)) -> FS | E33: =IF(LEN('pH measurement'!$C33)>6,LEFT(C33,2),1) -> 1 | F33: =IF(LEN('pH measurement'!$C33)>6,RIGHT(LEFT('pH measurement'!$C33,9),1),RIGHT(C33,1)) -> 1 | G33: 5.15 | L33: 78 | M33: 381 | N33: 25-P6S4C1FS | O33: FS | P33: 25 | Q33: 1
A34: 14 | B34: 1052 | C34: =VLOOKUP(B34,Hoja2!A$2:B$872,2,FALSE) -> 13FS1 | D34: =IF(LEN('pH measurement'!C34)>6,RIGHT(LEFT('pH measurement'!C34,11),2),RIGHT((LEFT(C34,4)),2)) -> FS | E34: =IF(LEN('pH measurement'!$C34)>6,LEFT(C34,2),1) -> 1 | F34: =IF(LEN('pH measurement'!$C34)>6,RIGHT(LEFT('pH measurement'!$C34,9),1),RIGHT(C34,1)) -> 1 | G34: 5.36 | L34: 51 | M34: 1002 | N34: 11AA2 | O34: AA | P34: 1 | Q34: 2
A35: 15 | B35: 139 | C35: =VLOOKUP(B35,Hoja2!A$2:B$872,2,FALSE) -> 25-P3S1C4FS | D35: =IF(LEN('pH measurement'!C35)>6,RIGHT(LEFT('pH measurement'!C35,11),2),RIGHT((LEFT(C35,4)),2)) -> FS | E35: =IF(LEN('pH measurement'!$C35)>6,LEFT(C35,2),1) -> 25 | F35: =IF(LEN('pH measurement'!$C35)>6,RIGHT(LEFT('pH measurement'!$C35,9),1),RIGHT(C35,1)) -> 4 | G35: 5.06 | L35: 86 | M35: 1044 | N35: 64AA2 | O35: AA | P35: 1 | Q35: 2
A36: 16 | B36: 148 | C36: =VLOOKUP(B36,Hoja2!A$2:B$872,2,FALSE) -> 25-P3S2C4AA | D36: =IF(LEN('pH measurement'!C36)>6,RIGHT(LEFT('pH measurement'!C36,11),2),RIGHT((LEFT(C36,4)),2)) -> AA | E36: =IF(LEN('pH measurement'!$C36)>6,LEFT(C36,2),1) -> 25 | F36: =IF(LEN('pH measurement'!$C36)>6,RIGHT(LEFT('pH measurement'!$C36,9),1),RIGHT(C36,1)) -> 4 | G36: 3.56 | L36: 61 | M36: 1083 | N36: 62FS2 | O36: FS | P36: 1 | Q36: 2
A37: 17 | B37: 1085 | C37: =VLOOKUP(B37,Hoja2!A$2:B$872,2,FALSE) -> 65AA1 | D37: =IF(LEN('pH measurement'!C37)>6,RIGHT(LEFT('pH measurement'!C37,11),2),RIGHT((LEFT(C37,4)),2)) -> AA | E37: =IF(LEN('pH measurement'!$C37)>6,LEFT(C37,2),1) -> 1 | F37: =IF(LEN('pH measurement'!$C37)>6,RIGHT(LEFT('pH measurement'!$C37,9),1),RIGHT(C37,1)) -> 1 | G37: 5.35 | L37: 58 | M37: 128 | N37: 10-P1S5C2AA | O37: AA | P37: 10 | Q37: 2
A38: 18 | B38: 1038 | C38: =VLOOKUP(B38,Hoja2!A$2:B$872,2,FALSE) -> 63AA2 | D38: =IF(LEN('pH measurement'!C38)>6,RIGHT(LEFT('pH measurement'!C38,11),2),RIGHT((LEFT(C38,4)),2)) -> AA | E38: =IF(LEN('pH measurement'!$C38)>6,LEFT(C38,2),1) -> 1 | F38: =IF(LEN('pH measurement'!$C38)>6,RIGHT(LEFT('pH measurement'!$C38,9),1),RIGHT(C38,1)) -> 2 | G38: 5.22 | L38: 62 | M38: 80 | N38: 10-P1S3C2AA | O38: AA | P38: 10 | Q38: 2
A39: 19 | B39: 138 | C39: =VLOOKUP(B39,Hoja2!A$2:B$872,2,FALSE) -> 25-P3S1C2FS | D39: =IF(LEN('pH measurement'!C39)>6,RIGHT(LEFT('pH measurement'!C39,11),2),RIGHT((LEFT(C39,4)),2)) -> FS | E39: =IF(LEN('pH measurement'!$C39)>6,LEFT(C39,2),1) -> 25 | F39: =IF(LEN('pH measurement'!$C39)>6,RIGHT(LEFT('pH measurement'!$C39,9),1),RIGHT(C39,1)) -> 2 | G39: 6.55 | L39: 73 | M39: 177 | N39: 10-P3S4C2AA | O39: AA | P39: 10 | Q39: 2
A40: 20 | B40: 1010 | C40: =VLOOKUP(B40,Hoja2!A$2:B$872,2,FALSE) -> 12FS1 | D40: =IF(LEN('pH measurement'!C40)>6,RIGHT(LEFT('pH measurement'!C40,11),2),RIGHT((LEFT(C40,4)),2)) -> FS | E40: =IF(LEN('pH measurement'!$C40)>6,LEFT(C40,2),1) -> 1 | F40: =IF(LEN('pH measurement'!$C40)>6,RIGHT(LEFT('pH measurement'!$C40,9),1),RIGHT(C40,1)) -> 1 | G40: 5.2 | L40: 90 | M40: 387 | N40: 10-P6S4C2AA -b | O40: AA | P40: 10 | Q40: 2
A41: 21 | B41: 78 | C41: =VLOOKUP(B41,Hoja2!A$2:B$872,2,FALSE) -> 25-P1S3C4FS | D41: =IF(LEN('pH measurement'!C41)>6,RIGHT(LEFT('pH measurement'!C41,11),2),RIGHT((LEFT(C41,4)),2)) -> FS | E41: =IF(LEN('pH measurement'!$C41)>6,LEFT(C41,2),1) -> 25 | F41: =IF(LEN('pH measurement'!$C41)>6,RIGHT(LEFT('pH measurement'!$C41,9),1),RIGHT(C41,1)) -> 4 | G41: 4.51 | L41: 91 | M41: 165 | N41: 10-P3S3C2AA | O41: AA | P41: 10 | Q41: 2
A42: 22 | B42: 6 | C42: =VLOOKUP(B42,Hoja2!A$2:B$872,2,FALSE) -> 25-P1S1C4FS | D42: =IF(LEN('pH measurement'!C42)>6,RIGHT(LEFT('pH measurement'!C42,11),2),RIGHT((LEFT(C42,4)),2)) -> FS | E42: =IF(LEN('pH measurement'!$C42)>6,LEFT(C42,2),1) -> 25 | F42: =IF(LEN('pH measurement'!$C42)>6,RIGHT(LEFT('pH measurement'!$C42,9),1),RIGHT(C42,1)) -> 4 | G42: 4.34 | L42: 77 | M42: 411 | N42: 10-P6S5C2FS -b | O42: FS | P42: 10 | Q42: 2
A43: 23 | B43: 175 | C43: =VLOOKUP(B43,Hoja2!A$2:B$872,2,FALSE) -> 25-P3S4C4FS | D43: =IF(LEN('pH measurement'!C43)>6,RIGHT(LEFT('pH measurement'!C43,11),2),RIGHT((LEFT(C43,4)),2)) -> FS | E43: =IF(LEN('pH measurement'!$C43)>6,LEFT(C43,2),1) -> 25 | F43: =IF(LEN('pH measurement'!$C43)>6,RIGHT(LEFT('pH measurement'!$C43,9),1),RIGHT(C43,1)) -> 4 | G43: 4.63 | L43: 79 | M43: 392 | N43: 10-P6S4C2FS | O43: FS | P43: 10 | Q43: 2
...

Sheet Hoja3
A3: Etiquetas de fila | B3: Promedio de pH | C3: Desvest de pH
A4: AA | B4: 5.1245682 | C4: 0.73546478 | F4: Abies
A5: 1 | B5: 5.17 | C5: 0.38011277 | F5: 1 | I5: 10 | L5: 25
A6: 1 | B6: 5.176 | C6: 0.35146835 | F6: 1 | G6: 2 | H6: 4 | I6: 1 | J6: 2 | K6: 4 | L6: 1 | M6: 2 | N6: 4
A7: 2 | B7: 5.492 | C7: 0.29693434 | E7: Avg | F7: 5.176 | G7: 5.492 | H7: 4.842 | I7: 5.658 | J7: 5.9602 | K7: 4.362 | L7: 5.585 | M7: 5.326 | N7: 3.812
A8: 4 | B8: 4.842 | C8: 0.1728294 | E8: Desv | F8: 0.35146835 | G8: 0.29693434 | H8: 0.1728294 | I8: 0.24539764 | J8: 0.16918983 | K8: 0.74065512 | L8: 0.30859898 | M8: 0.41385988 | N8: 0.2225309
A9: 10 | B9: 5.3267333 | C9: 0.83487813 | E9: STD Error | F9: =F8/SQRT(5) -> 0.15718142 | G9: =G8/SQRT(5) -> 0.13279307 | H9: =H8/SQRT(5) -> 0.077291655 | I9: =I8/SQRT(5) -> 0.10974516 | J9: =J8/SQRT(5) -> 0.075663994 | K9: =K8/SQRT(5) -> 0.33123104 | L9: =L8/SQRT(5) -> 0.13800966 | M9: =M8/SQRT(5) -> 0.18508376 | N9: =N8/SQRT(5) -> 0.099518842
A10: 1 | B10: 5.658 | C10: 0.24539764 | F10: Fagus
A11: 2 | B11: 5.9602 | C11: 0.16918983 | F11: 1 | I11: 10 | L11: 25
A12: 4 | B12: 4.362 | C12: 0.74065512 | F12: 1 | G12: 2 | H12: 4 | I12: 1 | J12: 2 | K12: 4 | L12: 1 | M12: 2 | N12: 4
A13: 25 | B13: 4.8592857 | C13: 0.87039747 | E13: Avg | F13: 5.294 | G13: 5.762 | H13: 5.27 | I13: 5.686 | J13: 4.974 | K13: 4.718 | L13: 5.7283333 | M13: 5.7 | N13: 4.822
A14: 1 | B14: 5.585 | C14: 0.30859898 | E14: Desv | F14: 0.11126545 | G14: 0.12029131 | H14: 0.22102036 | I14: 0.29099828 | J14: 0.33246052 | K14: 0.34441254 | L14: 0.23155273 | M14: 0.54313902 | N14: 0.49565109
A15: 2 | B15: 5.326 | C15: 0.41385988 | E15: STD Error | F15: =F14/SQRT(5) -> 0.049759421 | G15: =G14/SQRT(5) -> 0.053795911 | H15: =H14/SQRT(5) -> 0.09884331 | I15: =I14/SQRT(5) -> 0.13013839 | J15: =J14/SQRT(5) -> 0.14868087 | K15: =K14/SQRT(5) -> 0.15402597 | L15: =L14/SQRT(5) -> 0.10355353 | M15: =M14/SQRT(5) -> 0.24289916 | N15: =N14/SQRT(5) -> 0.2216619
A16: 4 | B16: 3.812 | C16: 0.2225309
A17: Birch | B17: 4.95 | C17: #DIV/0!
A18: (en blanco) | B18: 4.95 | C18: #DIV/0!
A19: (en blanco) | B19: 4.95 | C19: #DIV/0!
A20: FS | B20: 5.3369565 | C20: 0.49466428
A21: 1 | B21: 5.442 | C21: 0.2767464
A22: 1 | B22: 5.294 | C22: 0.11126545
A23: 2 | B23: 5.762 | C23: 0.12029131
A24: 4 | B24: 5.27 | C24: 0.22102036
A25: 10 | B25: 5.126 | C25: 0.51900729
A26: 1 | B26: 5.686 | C26: 0.29099828
A27: 2 | B27: 4.974 | C27: 0.33246052
A28: 4 | B28: 4.718 | C28: 0.34441254
A29: 25 | B29: 5.43625 | C29: 0.58747908
A30: 1 | B30: 5.7283333 | C30: 0.23155273
A31: 2 | B31: 5.7 | C31: 0.54313902
A32: 4 | B32: 4.822 | C32: 0.49565109
A33: Total general | B33: 5.230011 | C33: 0.6268436

Sheet Lignin measurement Plates
A1: Final plate 1 | P1: Results
B2: 1 | C2: 2 | D2: 3 | E2: 4 | F2: 5 | G2: 6 | H2: 7 | I2: 8 | J2: 9 | K2: 10 | L2: 11 | M2: 12 | P2: Actual Temperature: | Q2: 23.3
A3: A | B3: 162 | E3: 150 | H3: 1023 | K3: Blank | R3: 1 | S3: 2 | T3: 3 | U3: 4 | V3: 5 | W3: 6 | X3: 7 | Y3: 8 | Z3: 9 | AA3: 10 | AB3: 11 | AC3: 12
A4: B | B4: 1070 | E4: 125 | H4: 1089 | K4: 176 | Q4: A | R4: 0.996 | S4: 0.966 | T4: 0.977 | U4: 0.91 | V4: 0.914 | W4: 0.953 | X4: 1.151 | Y4: 1.181 | Z4: 1.217 | AA4: 0.24 | AB4: 0.234 | AC4: 0.245 | AD4: 205
A5: C | B5: 171 | E5: 1019 | H5: 1032 | K5: 146 | R5: 0.757 | S5: 0.727 | T5: 0.737 | U5: 0.67 | V5: 0.675 | W5: 0.714 | X5: 0.911 | Y5: 0.941 | Z5: 0.977 | AA5: 0.001 | AB5: -0.006 | AC5: 0.005 | AD5: Blank 205
A6: D | B6: 1086 | E6: 1055 | H6: 189 | K6: ???? | Q6: B | R6: 1.098 | S6: 1.166 | T6: 1.122 | U6: 0.946 | V6: 0.952 | W6: 0.968 | X6: 1.04 | Y6: 1.079 | Z6: 1.068 | AA6: 0.943 | AB6: 0.483 | AC6: 0.486 | AD6: 205
A7: E | B7: 1047 | E7: 708 | H7: ????1 | K7: 1007 | R7: 0.859 | S7: 0.927 | T7: 0.883 | U7: 0.707 | V7: 0.712 | W7: 0.728 | X7: 0.801 | Y7: 0.839 | Z7: 0.828 | AA7: 0.704 | AB7: 0.243 | AC7: 0.247 | AD7: Blank 205
A8: F | B8: 149 | E8: 1027 | H8: 1063 | K8: 1025 | Q8: C | R8: 0.355 | S8: 0.344 | T8: 0.364 | U8: 0.473 | V8: 0.439 | W8: 0.441 | X8: 0.402 | Y8: 0.419 | Z8: 0.411 | AA8: 0.391 | AB8: 0.409 | AC8: 0.421 | AD8: 205
A9: G | B9: 1039 | E9: 40 | H9: 120 | K9: 84 | R9: 0.115 | S9: 0.104 | T9: 0.124 | U9: 0.233 | V9: 0.199 | W9: 0.201 | X9: 0.162 | Y9: 0.179 | Z9: 0.171 | AA9: 0.152 | AB9: 0.169 | AC9: 0.181 | AD9: Blank 205
A10: H | B10: 170 | E10: 157 | H10: 409 | K10: 373 | Q10: D | R10: 0.364 | S10: 0.363 | T10: 0.36 | U10: 0.406 | V10: 0.422 | W10: 0.426 | X10: 0.44 | Y10: 0.436 | Z10: 0.448 | AA10: 0.904 | AB10: 0.916 | AC10: 0.946 | AD10: 205
R11: 0.124 | S11: 0.123 | T11: 0.12 | U11: 0.167 | V11: 0.182 | W11: 0.187 | X11: 0.2 | Y11: 0.197 | Z11: 0.208 | AA11: 0.665 | AB11: 0.676 | AC11: 0.706 | AD11: Blank 205
Q12: E | R12: 1.042 | S12: 1.017 | T12: 1.026 | U12: 0.458 | V12: 0.423 | W12: 0.497 | X12: 0.927 | Y12: 0.872 | Z12: 0.875 | AA12: 0.451 | AB12: 0.506 | AC12: 0.437 | AD12: 205
R13: 0.802 | S13: 0.777 | T13: 0.786 | U13: 0.218 | V13: 0.183 | W13: 0.257 | X13: 0.688 | Y13: 0.632 | Z13: 0.635 | AA13: 0.211 | AB13: 0.266 | AC13: 0.198 | AD13: Blank 205
Q14: F | R14: 0.76 | S14: 0.78 | T14: 0.792 | U14: 0.448 | V14: 0.44 | W14: 0.432 | X14: 0.473 | Y14: 0.478 | Z14: 0.478 | AA14: 0.406 | AB14: 0.384 | AC14: 0.367 | AD14: 205
R15: 0.521 | S15: 0.54 | T15: 0.553 | U15: 0.208 | V15: 0.2 | W15: 0.192 | X15: 0.234 | Y15: 0.238 | Z15: 0.239 | AA15: 0.167 | AB15: 0.144 | AC15: 0.127 | AD15: Blank 205
B16: + | Q16: G | R16: 0.53 | S16: 0.515 | T16: 0.489 | U16: 0.964 | V16: 0.964 | W16: 0.991 | X16: 1.035 | Y16: 1.039 | Z16: 1.062 | AA16: 0.991 | AB16: 0.977 | AC16: 1.124 | AD16: 205
R17: 0.291 | S17: 0.276 | T17: 0.249 | U17: 0.724 | V17: 0.725 | W17: 0.752 | X17: 0.795 | Y17: 0.799 | Z17: 0.822 | AA17: 0.751 | AB17: 0.737 | AC17: 0.885 | AD17: Blank 205
Q18: H | R18: 0.392 | S18: 0.391 | T18: 0.473 | U18: 1.136 | V18: 1.144 | W18: 1.135 | X18: 0.986 | Y18: 0.987 | Z18: 0.994 | AA18: 1.015 | AB18: 1.057 | AC18: 1.035 | AD18: 205
R19: 0.152 | S19: 0.151 | T19: 0.233 | U19: 0.896 | V19: 0.904 | W19: 0.895 | X19: 0.746 | Y19: 0.748 | Z19: 0.755 | AA19: 0.775 | AB19: 0.817 | AC19: 0.795 | AD19: Blank 205
A22: Final plate 2
B23: 1 | C23: 2 | D23: 3 | E23: 4 | F23: 5 | G23: 6 | H23: 7 | I23: 8 | J23: 9 | K23: 10 | L23: 11 | M23: 12 | R23: 1 | S23: 2 | T23: 3 | U23: 4 | V23: 5 | W23: 6 | X23: 7 | Y23: 8 | Z23: 9 | AA23: 10 | AB23: 11 | AC23: 12
A24: A | Q24: A | R24: 0.293 | S24: 0.235 | T24: 0.218 | U24: 0.214 | V24: 0.216 | W24: 0.223 | X24: 0.239 | Y24: 0.225 | Z24: 0.231 | AA24: 0.229 | AB24: 0.226 | AC24: 0.27 | AD24: 205
A25: B | R25: 0.069 | S25: 0.011 | T25: -0.006 | U25: -0.01 | V25: -0.007 | W25: -0.001 | X25: 0.016 | Y25: 0.001 | Z25: 0.007 | AA25: 0.006 | AB25: 0.003 | AC25: 0.046 | AD25: Blank 205
A26: C | K26: 7 | Q26: B | R26: 0.225 | S26: 0.229 | T26: 0.234 | U26: 0.222 | V26: 0.241 | W26: 0.212 | X26: 0.223 | Y26: 0.225 | Z26: 0.224 | AA26: 0.224 | AB26: 0.216 | AC26: 0.223 | AD26: 205
A27: D | B27: Blank | H27: 142 | K27: 368 | R27: 0.001 | S27: 0.005 | T27: 0.011 | U27: -0.002 | V27: 0.018 | W27: -0.011 | X27: 0 | Y27: 0.001 | Z27: 0 | AA27: 0 | AB27: -0.007 | AC27: -0.001 | AD27: Blank 205
A28: E | B28: 1003 | E28: 3 | H28: 331 | K28: 127 | Q28: C | R28: 0.218 | S28: 0.21 | T28: 0.218 | U28: 0.215 | V28: 0.222 | W28: 0.217 | X28: 0.216 | Y28: 0.21 | Z28: 0.216 | AA28: 0.327 | AB28: 0.339 | AC28: 0.329 | AD28: 205
A29: F | B29: 362 | E29: 385 | H29: 118 | K29: 1018 | R29: -0.006 | S29: -0.013 | T29: -0.006 | U29: -0.009 | V29: -0.002 | W29: -0.007 | X29: -0.008 | Y29: -0.014 | Z29: -0.008 | AA29: 0.103 | AB29: 0.115 | AC29: 0.105 | AD29: Blank 205
A30: G | B30: 355 | E30: 1048 | H30: 396 | K30: 324 | Q30: D | R30: 0.227 | S30: 0.222 | T30: 0.222 | U30: 0.221 | V30: 0.208 | W30: 0.217 | X30: 0.479 | Y30: 0.451 | Z30: 0.445 | AA30: 0.349 | AB30: 0.344 | AC30: 0.342 | AD30: 205
A31: H | B31: 344 | E31: 75 | H31: 326 | K31: 361 | R31: 0.003 | S31: -0.002 | T31: -0.001 | U31: -0.003 | V31: -0.015 | W31: -0.007 | X31: 0.255 | Y31: 0.227 | Z31: 0.222 | AA31: 0.126 | AB31: 0.12 | AC31: 0.118 | AD31: Blank 205
Q32: E | R32: 0.456 | S32: 0.439 | T32: 0.425 | U32: 0.448 | V32: 0.446 | W32: 0.453 | X32: 0.337 | Y32: 0.33 | Z32: 0.328 | AA32: 0.344 | AB32: 0.338 | AC32: 0.347 | AD32: 205
R33: 0.232 | S33: 0.216 | T33: 0.201 | U33: 0.224 | V33: 0.222 | W33: 0.229 | X33: 0.114 | Y33: 0.106 | Z33: 0.104 | AA33: 0.12 | AB33: 0.114 | AC33: 0.123 | AD33: Blank 205
Q34: F | R34: 0.671 | S34: 0.641 | T34: 0.643 | U34: 0.343 | V34: 0.332 | W34: 0.343 | X34: 0.932 | Y34: 0.915 | Z34: 0.89 | AA34: 0.91 | AB34: 0.925 | AC34: 0.918 | AD34: 205
R35: 0.448 | S35: 0.417 | T35: 0.419 | U35: 0.119 | V35: 0.108 | W35: 0.119 | X35: 0.709 | Y35: 0.692 | Z35: 0.666 | AA35: 0.686 | AB35: 0.701 | AC35: 0.694 | AD35: Blank 205
Q36: G | R36: 1.493 | S36: 1.436 | T36: 1.418 | U36: 1.073 | V36: 1.095 | W36: 1.098 | X36: 0.379 | Y36: 0.363 | Z36: 0.432 | AA36: 0.352 | AB36: 0.373 | AC36: 0.369 | AD36: 205
