Workbook

Sheet C N
A1: IDENTIFICACION MUESTRA | B1: Identificación | C1: Ntotal (g/100g) | D1: Ctotal (g/100g) | E1: DeWood code | F1: Species | G1: Class | H1: Diameter
A2: 250322 RaquelEsteban 2768-1 | B2: =RIGHT(A2, LEN(A2)-21) -> 2768-1 | C2: 0.660395 | D2: 46.057 | E2: =VLOOKUP(B2,'CEBAS-DEWOOD code'!A$2:B$302,2,FALSE) -> 114 | F2: =VLOOKUP(E2,'Field Table'!A$2:E$661,3,FALSE) -> FS | G2: =VLOOKUP(E2,'Field Table'!A$2:E$661,4,FALSE) -> 4 | H2: =VLOOKUP(E2,'Field Table'!A$2:E$661,5,FALSE) -> 25
A3: 250322 RaquelEsteban 2768-2 | B3: =RIGHT(A3, LEN(A3)-21) -> 2768-2 | C3: 0.19467 | D3: 46.557 | E3: =VLOOKUP(B3,'CEBAS-DEWOOD code'!A$2:B$302,2,FALSE) -> 364 | F3: =VLOOKUP(E3,'Field Table'!A$2:E$661,3,FALSE) -> FS | G3: =VLOOKUP(E3,'Field Table'!A$2:E$661,4,FALSE) -> 2 | H3: =VLOOKUP(E3,'Field Table'!A$2:E$661,5,FALSE) -> 25
A4: 250322 RaquelEsteban 2768-3 | B4: =RIGHT(A4, LEN(A4)-21) -> 2768-3 | C4: 0.152136 | D4: 45.2314 | E4: =VLOOKUP(B4,'CEBAS-DEWOOD code'!A$2:B$302,2,FALSE) -> 37 | F4: =VLOOKUP(E4,'Field Table'!A$2:E$661,3,FALSE) -> AA | G4: =VLOOKUP(E4,'Field Table'!A$2:E$661,4,FALSE) -> 1 | H4: =VLOOKUP(E4,'Field Table'!A$2:E$661,5,FALSE) -> 25
A5: 250322 RaquelEsteban 2768-4 | B5: =RIGHT(A5, LEN(A5)-21) -> 2768-4 | C5: 0.1069 | D5: 51.737 | E5: =VLOOKUP(B5,'CEBAS-DEWOOD code'!A$2:B$302,2,FALSE) -> 172 | F5: =VLOOKUP(E5,'Field Table'!A$2:E$661,3,FALSE) -> AA | G5: =VLOOKUP(E5,'Field Table'!A$2:E$661,4,FALSE) -> 4 | H5: =VLOOKUP(E5,'Field Table'!A$2:E$661,5,FALSE) -> 25
A6: 250322 RaquelEsteban 2768-5 | B6: =RIGHT(A6, LEN(A6)-21) -> 2768-5 | C6: 0.17723 | D6: 46.113 | E6: =VLOOKUP(B6,'CEBAS-DEWOOD code'!A$2:B$302,2,FALSE) -> 192 | F6: =VLOOKUP(E6,'Field Table'!A$2:E$661,3,FALSE) -> FS | G6: =VLOOKUP(E6,'Field Table'!A$2:E$661,4,FALSE) -> 2 | H6: =VLOOKUP(E6,'Field Table'!A$2:E$661,5,FALSE) -> 10
A7: 250322 RaquelEsteban 2768-6 | B7: =RIGHT(A7, LEN(A7)-21) -> 2768-6 | C7: 0.12427 | D7: 47.552 | E7: =VLOOKUP(B7,'CEBAS-DEWOOD code'!A$2:B$302,2,FALSE) -> #N/A | F7: =VLOOKUP(E7,'Field Table'!A$2:E$661,3,FALSE) -> #N/A | G7: =VLOOKUP(E7,'Field Table'!A$2:E$661,4,FALSE) -> #N/A | H7: =VLOOKUP(E7,'Field Table'!A$2:E$661,5,FALSE) -> #N/A
A8: 250322 RaquelEsteban 2768-7 | B8: =RIGHT(A8, LEN(A8)-21) -> 2768-7 | C8: 0.40786 | D8: 47.855 | E8: =VLOOKUP(B8,'CEBAS-DEWOOD code'!A$2:B$302,2,FALSE) -> 1011 | F8: =VLOOKUP(E8,'Field Table'!A$2:E$661,3,FALSE) -> FS | G8: =VLOOKUP(E8,'Field Table'!A$2:E$661,4,FALSE) -> 2 | H8: =VLOOKUP(E8,'Field Table'!A$2:E$661,5,FALSE) -> 01
A9: 250322 RaquelEsteban 2768-8 | B9: =RIGHT(A9, LEN(A9)-21) -> 2768-8 | C9: 0.18547 | D9: 48.079 | E9: =VLOOKUP(B9,'CEBAS-DEWOOD code'!A$2:B$302,2,FALSE) -> 129 | F9: =VLOOKUP(E9,'Field Table'!A$2:E$661,3,FALSE) -> AA | G9: =VLOOKUP(E9,'Field Table'!A$2:E$661,4,FALSE) -> 4 | H9: =VLOOKUP(E9,'Field Table'!A$2:E$661,5,FALSE) -> 10
A10: 250322 RaquelEsteban 2768-9 | B10: =RIGHT(A10, LEN(A10)-21) -> 2768-9 | C10: 0.12813 | D10: 46.988 | E10: =VLOOKUP(B10,'CEBAS-DEWOOD code'!A$2:B$302,2,FALSE) -> 137 | F10: =VLOOKUP(E10,'Field Table'!A$2:E$661,3,FALSE) -> FS | G10: =VLOOKUP(E10,'Field Table'!A$2:E$661,4,FALSE) -> 1 | H10: =VLOOKUP(E10,'Field Table'!A$2:E$661,5,FALSE) -> 25
A11: 250322 RaquelEsteban 2768-10 | B11: =RIGHT(A11, LEN(A11)-21) -> 2768-10 | C11: 0.3178 | D11: 37.698 | E11: =VLOOKUP(B11,'CEBAS-DEWOOD code'!A$2:B$302,2,FALSE) -> 1090 | F11: =VLOOKUP(E11,'Field Table'!A$2:E$661,3,FALSE) -> FS | G11: =VLOOKUP(E11,'Field Table'!A$2:E$661,4,FALSE) -> 4 | H11: =VLOOKUP(E11,'Field Table'!A$2:E$661,5,FALSE) -> 01
A12: 250322 RaquelEsteban 2768-11 | B12: =RIGHT(A12, LEN(A12)-21) -> 2768-11 | C12: 0.14039 | D12: 47.2665 | E12: =VLOOKUP(B12,'CEBAS-DEWOOD code'!A$2:B$302,2,FALSE) -> 381 | F12: =VLOOKUP(E12,'Field Table'!A$2:E$661,3,FALSE) -> FS | G12: =VLOOKUP(E12,'Field Table'!A$2:E$661,4,FALSE) -> 1 | H12: =VLOOKUP(E12,'Field Table'!A$2:E$661,5,FALSE) -> 25
A13: 250322 RaquelEsteban 2768-12 | B13: =RIGHT(A13, LEN(A13)-21) -> 2768-12 | C13: 0.10321 | D13: 47.593 | E13: =VLOOKUP(B13,'CEBAS-DEWOOD code'!A$2:B$302,2,FALSE) -> 75 | F13: =VLOOKUP(E13,'Field Table'!A$2:E$661,3,FALSE) -> AA | G13: =VLOOKUP(E13,'Field Table'!A$2:E$661,4,FALSE) -> 4 | H13: =VLOOKUP(E13,'Field Table'!A$2:E$661,5,FALSE) -> 25
... A300: 250322 RaquelEsteban 2775-30 | B300: =RIGHT(A300, LEN(A300)-21) -> 2775-30 | C300: 0.09985 | D300: 47.677 | E300: =VLOOKUP(B300,'CEBAS-DEWOOD code'!A$2:B$302,2,FALSE) -> 170 | F300: =VLOOKUP(E300,'Field Table'!A$2:E$661,3,FALSE) -> AA | G300: =VLOOKUP(E300,'Field Table'!A$2:E$661,4,FALSE) -> 1 | H300: =VLOOKUP(E300,'Field Table'!A$2:E$661,5,FALSE) -> 25

Sheet IONOMICS
A1: IDENTIFICACION MUESTRA | B1: Identificación | C1: DeWood code | D1: Species | E1: Class | F1: Diameter | G1: Al (mg/Kg) | H1: As (mg/Kg) | I1: Be (mg/Kg) | J1: Bi (mg/Kg) | K1: B (mg/Kg) | L1: Ca (g/100g) | M1: Cd (mg/Kg) | N1: Co (mg/Kg) | O1: Cr (mg/Kg) | P1: Cu (mg/Kg) | Q1: Fe (mg/Kg) | R1: K (g/100g) | S1: La (mg/Kg) | T1: Li (mg/Kg) | U1: Mg (g/100g) | V1: Mn (mg/Kg) | W1: Mo (mg/Kg) | X1: Na (g/100g) | Y1: Ni (mg/Kg) | Z1: Pb (mg/Kg) | AA1: P (g/100g) | AB1: Rb (mg/Kg) | AC1: Sb (mg/Kg) | AD1: Se (mg/Kg) | AE1: Si (mg/Kg) | AF1: S (g/100g) | AG1: Sr (mg/Kg) | AH1: Ti (mg/Kg) | AI1: Tl (mg/Kg) | AJ1: V (mg/Kg) | AK1: Zn (mg/Kg)
A2: EHU ION2768-1 | B2: =RIGHT(A2, LEN(A2)-7) -> 2768-1 | C2: =VLOOKUP(B2,'CEBAS-DEWOOD code'!A$2:B$302,2,FALSE) -> 114 | D2: =VLOOKUP(IONOMICS!C2,'Field Table'!A$2:E$661,3,FALSE) -> FS | E2: =VLOOKUP(IONOMICS!C2,'Field Table'!A$2:E$661,4,FALSE) -> 4 | F2: =VLOOKUP(IONOMICS!C2,'Field Table'!A$2:E$661,5,FALSE) -> 25 | G2: 71.41174 | H2: <0,01 | I2: <0,01 | J2: <0,01 | K2: <0,01 | L2: 0.69837189 | M2: 0.13924593 | N2: 0.096401028 | O2: 0.22493573 | P2: 2.7634961 | Q2: 40.949015 | R2: 0.12350043 | S2: <0,01 | T2: 0.33204799 | U2: 0.062907027 | V2: 262.31791 | W2: <0,01 | X2: 0.0026563839 | Y2: 2.3671808 | Z2: 0.53556127 | AA2: 0.02001928 | AB2: 1.8958869 | AC2: <0,01 | AD2: <0,01 | AE2: 133.67609 | AF2: 0.031533847 | AG2: 42.22365 | AH2: 2.4207369 | AI2: 2.3993145 | AJ2: <0,01 | AK2: 8.172665
A3: EHU ION2768-2 | B3: =RIGHT(A3, LEN(A3)-7) -> 2768-2 | C3: =VLOOKUP(B3,'CEBAS-DEWOOD code'!A$2:B$302,2,FALSE) -> 364 | D3: =VLOOKUP(IONOMICS!C3,'Field Table'!A$2:E$661,3,FALSE) -> FS | E3: =VLOOKUP(IONOMICS!C3,'Field Table'!A$2:E$661,4,FALSE) -> 2 | F3: =VLOOKUP(IONOMICS!C3,'Field Table'!A$2:E$661,5,FALSE) -> 25 | G3: 4.3090639 | H3: <0,01 | I3: <0,01 | J3: <0,01 | K3: <0,01 | L3: 0.09372214 | M3: 0.061911838 | N3: 0.037147103 | O3: 0.04952947 | P3: 1.1267954 | Q3: 7.3055968 | R3: 0.14945518 | S3: <0,01 | T3: 0.29717682 | U3: 0.031500743 | V3: 47.201585 | W3: <0,01 | X3: 0.00030708271 | Y3: 0.44576523 | Z3: 0.14858841 | AA3: 0.0082305597 | AB3: 5.2996533 | AC3: <0,01 | AD3: <0,01 | AE3: 12.506191 | AF3: 0.012275879 | AG3: 8.5562159 | AH3: 0.4581476 | AI3: <0,01 | AJ3: <0,01 | AK3: 2.8107974
A4: EHU ION2768-3 | B4: =RIGHT(A4, LEN(A4)-7) -> 2768-3 | C4: =VLOOKUP(B4,'CEBAS-DEWOOD code'!A$2:B$302,2,FALSE) -> 37 | D4: =VLOOKUP(IONOMICS!C4,'Field Table'!A$2:E$661,3,FALSE) -> AA | E4: =VLOOKUP(IONOMICS!C4,'Field Table'!A$2:E$661,4,FALSE) -> 1 | F4: =VLOOKUP(IONOMICS!C4,'Field Table'!A$2:E$661,5,FALSE) -> 25 | G4: 18.125299 | H4: 0.10760402 | I4: <0,01 | J4: <0,01 | K4: <0,01 | L4: 0.063928742 | M4: 0.071736011 | N4: 0.035868006 | O4: <0,01 | P4: 1.8292683 | Q4: 5.4280249 | R4: 0.14395026 | S4: <0,01 | T4: 0.10760402 | U4: 0.014155906 | V4: 30.547585 | W4: <0,01 | X4: <0,01 | Y4: 0.17934003 | Z4: 0.38259206 | AA4: 0.0018173123 | AB4: 3.3118125 | AC4: <0,01 | AD4: <0,01 | AE4: 85.246294 | AF4: 0.0048995696 | AG4: 3.7183166 | AH4: 1.6977523 | AI4: <0,01 | AJ4: <0,01 | AK4: 3.8498326
A5: EHU ION2768-4 | B5: =RIGHT(A5, LEN(A5)-7) -> 2768-4 | C5: =VLOOKUP(B5,'CEBAS-DEWOOD code'!A$2:B$302,2,FALSE) -> 172 | D5: =VLOOKUP(IONOMICS!C5,'Field Table'!A$2:E$661,3,FALSE) -> AA | E5: =VLOOKUP(IONOMICS!C5,'Field Table'!A$2:E$661,4,FALSE) -> 4 | F5: =VLOOKUP(IONOMICS!C5,'Field Table'!A$2:E$661,5,FALSE) -> 25 | G5: 14.127848 | H5: 0.12750765 | I5: <0,01 | J5: <0,01 | K5: <0,01 | L5: 0.1232574 | M5: 0.16150969 | N5: <0,01 | O5: 0.03400204 | P5: 2.932676 | Q5: 3.7232234 | R5: 0.15062904 | S5: <0,01 | T5: 0.12750765 | U5: 0.0093250595 | V5: 31.196872 | W5: <0,01 | X5: 0.00057378443 | Y5: 0.18701122 | Z5: 0.41652499 | AA5: 0.001183271 | AB5: 2.8646719 | AC5: <0,01 | AD5: <0,01 | AE5: 11.203672 | AF5: 0.0076844611 | AG5: 8.7895274 | AH5: 0.21251275 | AI5: <0,01 | AJ5: <0,01 | AK5: 2.5246515
A6: EHU ION2768-5 | B6: =RIGHT(A6, LEN(A6)-7) -> 2768-5 | C6: =VLOOKUP(B6,'CEBAS-DEWOOD code'!A$2:B$302,2,FALSE) -> 192 | D6: =VLOOKUP(IONOMICS!C6,'Field Table'!A$2:E$661,3,FALSE) -> FS | E6: =VLOOKUP(IONOMICS!C6,'Field Table'!A$2:E$661,4,FALSE) -> 2 | F6: =VLOOKUP(IONOMICS!C6,'Field Table'!A$2:E$661,5,FALSE) -> 10 | G6: 4.0416667 | H6: 0.020833333 | I6: <0,01 | J6: <0,01 | K6: <0,01 | L6: 0.19875 | M6: 0.0625 | N6: 0.020833333 | O6: <0,01 | P6: 1.2708333 | Q6: 5.7708333 | R6: 0.085041667 | S6: <0,01 | T6: 0.03125 | U6: 0.041395833 | V6: 48.729167 | W6: <0,01 | X6: 0.000540625 | Y6: 0.65625 | Z6: 0.09375 | AA6: 0.00558125 | AB6: 1.96875 | AC6: <0,01 | AD6: <0,01 | AE6: 52.260417 | AF6: 0.010115625 | AG6: 11.572917 | AH6: 0.58333333 | AI6: <0,01 | AJ6: <0,01 | AK6: 2.15625
A7: EHU ION2768-6 | B7: =RIGHT(A7, LEN(A7)-7) -> 2768-6 | C7: =VLOOKUP(B7,'CEBAS-DEWOOD code'!A$2:B$302,2,FALSE) -> #N/A | D7: =VLOOKUP(IONOMICS!C7,'Field Table'!A$2:E$661,3,FALSE) -> #N/A | E7: =VLOOKUP(IONOMICS!C7,'Field Table'!A$2:E$661,4,FALSE) -> #N/A | F7: =VLOOKUP(IONOMICS!C7,'Field Table'!A$2:E$661,5,FALSE) -> #N/A | G7: 18.069837 | H7: <0,01 | I7: <0,01 | J7: <0,01 | K7: <0,01 | L7: 0.059811482 | M7: 0.1285347 | N7: <0,01 | O7: 0.1285347 | P7: 0.88903171 | Q7: 7.7977721 | R7: 0.15756213 | S7: <0,01 | T7: 0.17137961 | U7: 0.013742502 | V7: 26.885176 | W7: <0,01 | X7: 0.00052806341 | Y7: 0.1285347 | Z7: 0.10711225 | AA7: 0.002281491 | AB7: 2.9241645 | AC7: <0,01 | AD7: <0,01 | AE7: 19.194516 | AF7: 0.0054680805 | AG7: 4.0059983 | AH7: 1.756641 | AI7: <0,01 | AJ7: <0,01 | AK7: 3.9417309
A8: EHU ION2768-7 | B8: =RIGHT(A8, LEN(A8)-7) -> 2768-7 | C8: =VLOOKUP(B8,'CEBAS-DEWOOD code'!A$2:B$302,2,FALSE) -> 1011 | D8: =VLOOKUP(IONOMICS!C8,'Field Table'!A$2:E$661,3,FALSE) -> FS | E8: =VLOOKUP(IONOMICS!C8,'Field Table'!A$2:E$661,4,FALSE) -> 2 | F8: =VLOOKUP(IONOMICS!C8,'Field Table'!A$2:E$661,5,FALSE) -> 01 | G8: 14.707977 | H8: <0,01 | I8: <0,01 | J8: <0,01 | K8: <0,01 | L8: 0.33784425 | M8: 0.059354226 | N8: <0,01 | O8: <0,01 | P8: 2.4097816 | Q8: 12.630579 | R8: 0.11602564 | S8: <0,01 | T8: 0.22554606 | U8: 0.037511871 | V8: 92.604463 | W8: <0,01 | X8: 0.00035137702 | Y8: 0.66476733 | Z8: 0.93779677 | AA8: 0.020880817 | AB8: 2.7065527 | AC8: <0,01 | AD8: <0,01 | AE8: 392.33143 | AF8: 0.021569326 | AG8: 20.78585 | AH8: 0.89031339 | AI8: <0,01 | AJ8: <0,01 | AK8: 5.828585
A9: EHU ION2768-8 | B9: =RIGHT(A9, LEN(A9)-7) -> 2768-8 | C9: =VLOOKUP(B9,'CEBAS-DEWOOD code'!A$2:B$302,2,FALSE) -> 129 | D9: =VLOOKUP(IONOMICS!C9,'Field Table'!A$2:E$661,3,FALSE) -> AA | E9: =VLOOKUP(IONOMICS!C9,'Field Table'!A$2:E$661,4,FALSE) -> 4 | F9: =VLOOKUP(IONOMICS!C9,'Field Table'!A$2:E$661,5,FALSE) -> 10 | G9: 15.119048 | H9: 0.021645022 | I9: <0,01 | J9: <0,01 | K9: <0,01 | L9: 0.30941558 | M9: 0.17316017 | N9: 0.032467532 | O9: 0.4978355 | P9: 1.3419913 | Q9: 4.9675325 | R9: 0.030984848 | S9: <0,01 | T9: 0.34632035 | U9: 0.036406926 | V9: 78.625541 | W9: <0,01 | X9: 0.00051839827 | Y9: 0.064935065 | Z9: 0.5952381 | AA9: 0.005 | AB9: 0.8008658 | AC9: <0,01 | AD9: <0,01 | AE9: 20.800866 | AF9: 0.013398268 | AG9: 16.980519 | AH9: 1.038961 | AI9: <0,01 | AJ9: <0,01 | AK9: 8.8744589
A10: EHU ION2768-9 | B10: =RIGHT(A10, LEN(A10)-7) -> 2768-9 | C10: =VLOOKUP(B10,'CEBAS-DEWOOD code'!A$2:B$302,2,FALSE) -> 137 | D10: =VLOOKUP(IONOMICS!C10,'Field Table'!A$2:E$661,3,FALSE) -> FS | E10: =VLOOKUP(IONOMICS!C10,'Field Table'!A$2:E$661,4,FALSE) -> 1 | F10: =VLOOKUP(IONOMICS!C10,'Field Table'!A$2:E$661,5,FALSE) -> 25 | G10: 4.9439552 | H10: <0,01 | I10: <0,01 | J10: <0,01 | K10: <0,01 | L10: 0.17183747 | M10: 0.060048038 | N10: <0,01 | O10: <0,01 | P10: 1.1008807 | Q10: 6.5352282 | R10: 0.068604884 | S10: <0,01 | T10: 0.090072058 | U10: 0.023528823 | V10: 50.160128 | W10: <0,01 | X10: 0.00019415532 | Y10: 0.79063251 | Z10: 0.050040032 | AA10: 0.0042774219 | AB10: 2.5420336 | AC10: <0,01 | AD10: <0,01 | AE10: 9.5576461 | AF10: 0.010118094 | AG10: 9.5376301 | AH10: 0.70056045 | AI10: <0,01 | AJ10: <0,01 | AK10: 3.9031225
A11: EHU ION2768-10 | B11: =RIGHT(A11, LEN(A11)-7) -> 2768-10 | C11: =VLOOKUP(B11,'CEBAS-DEWOOD code'!A$2:B$302,2,FALSE) -> 1090 | D11: =VLOOKUP(IONOMICS!C11,'Field Table'!A$2:E$661,3,FALSE) -> FS | E11: =VLOOKUP(IONOMICS!C11,'Field Table'!A$2:E$661,4,FALSE) -> 4 | F11: =VLOOKUP(IONOMICS!C11,'Field Table'!A$2:E$661,5,FALSE) -> 01 | G11: 24.918869 | H11: 0.17385257 | I11: <0,01 | J11: <0,01 | K11: <0,01 | L11: 0.30992119 | M11: 0.12749189 | N11: <0,01 | O11: 0.23180343 | P11: 2.4455262 | Q11: 16.539175 | R11: 0.03853732 | S11: <0,01 | T11: 0.20862309 | U11: 0.028569773 | V11: 145.10895 | W11: <0,01 | X11: 0.00072670376 | Y11: 0.56791841 | Z11: 1.1358368 | AA11: 0.015971256 | AB11: 0.71859064 | AC11: <0,01 | AD11: <0,01 | AE11: 268.31247 | AF11: 0.021986555 | AG11: 16.458044 | AH11: 1.2285582 | AI11: <0,01 | AJ11: <0,01 | AK11: 9.6777932
A12: EHU ION2768-11 | B12: =RIGHT(A12, LEN(A12)-7) -> 2768-11 | C12: =VLOOKUP(B12,'CEBAS-DEWOOD code'!A$2:B$302,2,FALSE) -> 381 | D12: =VLOOKUP(IONOMICS!C12,'Field Table'!A$2:E$661,3,FALSE) -> FS | E12: =VLOOKUP(IONOMICS!C12,'Field Table'!A$2:E$661,4,FALSE) -> 1 | F12: =VLOOKUP(IONOMICS!C12,'Field Table'!A$2:E$661,5,FALSE) -> 25 | G12: 2.024827 | H12: 0.1017501 | I12: <0,01 | J12: <0,01 | K12: <0,01 | L12: 0.074399674 | M12: 0.13227513 | N12: 0.050875051 | O12: 0.091575092 | P12: 0.82417582 | Q12: 2.6963777 | R12: 0.096886447 | S12: <0,01 | T12: 0.081400081 | U12: 0.012698413 | V12: 51.638177 | W12: <0,01 | X12: 0.00026048026 | Y12: 1.4855515 | Z12: 0.23402523 | AA12: 0.0050579976 | AB12: 2.8490028 | AC12: <0,01 | AD12: <0,01 | AE12: 8.6284086 | AF12: 0.0091310541 | AG12: 6.6137566 | AH12: 0.22385022 | AI12: <0,01 | AJ12: <0,01 | AK12: 5.5250305
A13: EHU ION2768-12 | B13: =RIGHT(A13, LEN(A13)-7) -> 2768-12 | C13: =VLOOKUP(B13,'CEBAS-DEWOOD code'!A$2:B$302,2,FALSE) -> 75 | D13: =VLOOKUP(IONOMICS!C13,'Field Table'!A$2:E$661,3,FALSE) -> AA | E13: =VLOOKUP(IONOMICS!C13,'Field Table'!A$2:E$661,4,FALSE) -> 4 | F13: =VLOOKUP(IONOMICS!C13,'Field Table'!A$2:E$661,5,FALSE) -> 25 | G13: 13.035781 | H13: 0.083861349 | I13: <0,01 | J13: <0,01 | K13: <0,01 | L13: 0.069241521 | M13: 0.23294819 | N13: <0,01 | O13: 0.1024972 | P13: 2.1244875 | Q13: 3.9042117 | R13: 0.053242639 | S13: <0,01 | T13: 0.14908684 | U13: 0.012476705 | V13: 56.410734 | W13: <0,01 | X13: 0.00020033545 | Y13: 0.037271711 | Z13: 0.21431234 | AA13: 0.0046310101 | AB13: 1.2392844 | AC13: <0,01 | AD13: <0,01 | AE13: 34.914275 | AF13: 0.0073080507 | AG13: 3.4196795 | AH13: 1.0715617 | AI13: <0,01 | AJ13: <0,01 | AK13: 3.5314946
A14: EHU ION2768-13 | B14: =RIGHT(A14, LEN(A14)-7) -> 2768-13 | C14: =VLOOKUP(B14,'CEBAS-DEWOOD code'!A$2:B$302,2,FALSE) -> 382 | D14: =VLOOKUP(IONOMICS!C14,'Field Table'!A$2:E$661,3,FALSE) -> FS | E14: =VLOOKUP(IONOMICS!C14,'Field Table'!A$2:E$661,4,FALSE) -> 2 | F14: =VLOOKUP(IONOMICS!C14,'Field Table'!A$2:E$661,5,FALSE) -> 25 | G14: 2.3767606 | H14: <0,01 | I14: <0,01 | J14: <0,01 | K14: <0,01 | L14: 0.14799736 | M14: 0.14304577 | N14: 0.044014085 | O14: <0,01 | P14: 1.2544014 | Q14: 7.4273768 | R14: 0.14106514 | S14: <0,01 | T14: 0.11003521 | U14: 0.059231954 | V14: 66.472271 | W14: <0,01 | X14: 0.00014854754 | Y14: 0.56117958 | Z14: 0.11003521 | AA14: 0.0029852553 | AB14: 5.9198944 | AC14: <0,01 | AD14: <0,01 | AE14: 10.002201 | AF14: 0.010768046 | AG14: 14.491637 | AH14: 1.4304577 | AI14: <0,01 | AJ14: <0,01 | AK14: 3.8732394
A15: EHU ION2768-14 | B15: =RIGHT(A15, LEN(A15)-7) -> 2768-14 | C15: =VLOOKUP(B15,'CEBAS-DEWOOD code'!A$2:B$302,2,FALSE) -> 350 | D15: =VLOOKUP(IONOMICS!C15,'Field Table'!A$2:E$661,3,FALSE) -> AA | E15: =VLOOKUP(IONOMICS!C15,'Field Table'!A$2:E$661,4,FALSE) -> 2 | F15: =VLOOKUP(IONOMICS!C15,'Field Table'!A$2:E$661,5,FALSE) -> 10 | G15: 36.551866 | H15: <0,01 | I15: <0,01 | J15: <0,01 | K15: <0,01 | L15: 0.068245182 | M15: 0.15375154 | N15: <0,01 | O15: 0.071750718 | P15: 0.75850759 | Q15: 3.5465355 | R15: 0.067876179 | S15: <0,01 | T15: 0.18450185 | U15: 0.018542435 | V15: 31.693317 | W15: <0,01 | X15: 0.00060578106 | Y15: 0.04100041 | Z15: 0.70725707 | AA15: 0.00082615826 | AB15: 1.1480115 | AC15: <0,01 | AD15: <0,01 | AE15: 4.0077901 | AF15: 0.0053690037 | AG15: 3.8437884 | AH15: 0.95325953 | AI15: <0,01 | AJ15: <0,01 | AK15: 5.0635506
A16: EHU ION2768-15 | B16: =RIGHT(A16, LEN(A16)-7) -> 2768-15 | C16: =VLOOKUP(B16,'CEBAS-DEWOOD code'!A$2:B$302,2,FALSE) -> 176 | D16: =VLOOKUP(IONOMICS!C16,'Field Table'!A$2:E$661,3,FALSE) -> AA | E16: =VLOOKUP(IONOMICS!C16,'Field Table'!A$2:E$661,4,FALSE) -> 1 | F16: =VLOOKUP(IONOMICS!C16,'Field Table'!A$2:E$661,5,FALSE) -> 10 | G16: 30.031447 | H16: 0.041928721 | I16: <0,01 | J16: <0,01 | K16: <0,01 | L16: 0.044633124 | M16: 0.073375262 | N16: 0.01048218 | O16: 0.062893082 | P16: 0.97484277 | Q16: 11.29979 | R16: 0.084119497 | S16: <0,01 | T16: 0.14675052 | U16: 0.011446541 | V16: 20.691824 | W16: <0,01 | X16: 0.00039203354 | Y16: 0.020964361 | Z16: 0.17819706 | AA16: 0.0012494759 | AB16: 1.4150943 | AC16: <0,01 | AD16: <0,01 | AE16: 164.25577 | AF16: 0.005942348 | AG16: 3.5744235 | AH16: 3.8888889 | AI16: <0,01 | AJ16: <0,01 | AK16: 2.3899371
A17: EHU ION2768-16 | B17: =RIGHT(A17, LEN(A17)-7) -> 2768-16 | C17: =VLOOKUP(B17,'CEBAS-DEWOOD code'!A$2:B$302,2,FALSE) -> 190 | D17: =VLOOKUP(IONOMICS!C17,'Field Table'!A$2:E$661,3,FALSE) -> AA | E17: =VLOOKUP(IONOMICS!C17,'Field Table'!A$2:E$661,4,FALSE) -> 4 | F17: =VLOOKUP(IONOMICS!C17,'Field Table'!A$2:E$661,5,FALSE) -> 10 | G17: 19.031311 | H17: 0.061154599 | I17: <0,01 | J17: <0,01 | K17: <0,01 | L17: 0.06715998 | M17: 0.02446184 | N17: 0.01223092 | O17: 0.19569472 | P17: 0.66046967 | Q17: 5.6751468 | R17: 0.22407045 | S17: <0,01 | T17: 0.25684932 | U17: 0.01115093 | V17: 53.938356 | W17: <0,01 | X17: 0.0017918297 | Y17: 0.66046967 | Z17: 0.33023483 | AA17: 0.013197162 | AB17: 5.3938356 | AC17: <0,01 | AD17: <0,01 | AE17: 16.450587 | AF17: 0.0096832192 | AG17: 4.5865949 | AH17: 0.51369863 | AI17: <0,01 | AJ17: <0,01 | AK17: 3.1311155
A18: EHU ION2768-17 | B18: =RIGHT(A18, LEN(A18)-7) -> 2768-17 | C18: =VLOOKUP(B18,'CEBAS-DEWOOD code'!A$2:B$302,2,FALSE) -> 1070 | D18: =VLOOKUP(IONOMICS!C18,'Field Table'!A$2:E$661,3,FALSE) -> FS | E18: =VLOOKUP(IONOMICS!C18,'Field Table'!A$2:E$661,4,FALSE) -> 1 | F18: =VLOOKUP(IONOMICS!C18,'Field Table'!A$2:E$661,5,FALSE) -> 01 | G18: 17.188089 | H18: <0,01 | I18: <0,01 | J18: <0,01 | K18: <0,01 | L18: 0.32632868 | M18: 0.084809649 | N18: 0.056539766 | O18: 0.094232944 | P18: 2.7327554 | Q18: 11.826234 | R18: 0.089342254 | S18: <0,01 | T18: 0.13192612 | U18: 0.024302676 | V18: 92.857143 | W18: <0,01 | X18: 0.00033641161 | Y18: 0.74444026 | Z18: 0.94232944 | AA18: 0.024010554 | AB18: 2.3464003 | AC18: <0,01 | AD18: <0,01 | AE18: 491.80173 | AF18: 0.020147003 | AG18: 20.768941 | AH18: 0.61251413 | AI18: <0,01 | AJ18: <0,01 | AK18: 10.836789
A19: EHU ION2768-18 | B19: =RIGHT(A19, LEN(A19)-7) -> 2768-18 | C19: =VLOOKUP(B19,'CEBAS-DEWOOD code'!A$2:B$302,2,FALSE) -> 1085 | D19: =VLOOKUP(IONOMICS!C19,'Field Table'!A$2:E$661,3,FALSE) -> AA | E19: =VLOOKUP(IONOMICS!C19,'Field Table'!A$2:E$661,4,FALSE) -> 1 | F19: =VLOOKUP(IONOMICS!C19,'Field Table'!A$2:E$661,5,FALSE) -> 01 | G19: 76.026971 | H19: <0,01 | I19: <0,01 | J19: <0,01 | K19: <0,01 | L19: 0.21431535 | M19: 0.54979253 | N19: <0,01 | O19: 0.36307054 | P19: 2.7074689 | Q19: 18.195021 | R19: 0.11493776 | S19: <0,01 | T19: 0.1659751 | U19: 0.02939834 | V19: 132.05394 | W19: <0,01 | X19: 0.00026556017 | Y19: 0.41493776 | Z19: 0.90248963 | AA19: 0.018858921 | AB19: 2.5207469 | AC19: <0,01 | AD19: <0,01 | AE19: 41.172199 | AF19: 0.015684647 | AG19: 9.159751 | AH19: 1.1929461 | AI19: <0,01 | AJ19: <0,01 | AK19: 18.371369
A20: EHU ION2768-19 | B20: =RIGHT(A20, LEN(A20)-7) -> 2768-19 | C20: =VLOOKUP(B20,'CEBAS-DEWOOD code'!A$2:B$302,2,FALSE) -> 191 | D20: =VLOOKUP(IONOMICS!C20,'Field Table'!A$2:E$661,3,FALSE) -> FS | E20: =VLOOKUP(IONOMICS!C20,'Field Table'!A$2:E$661,4,FALSE) -> 1 | F20: =VLOOKUP(IONOMICS!C20,'Field Table'!A$2:E$661,5,FALSE) -> 10 | G20: 6.2980031 | H20: 0.14400922 | I20: <0,01 | J20: <0,01 | K20: <0,01 | L20: 0.36866359 | M20: 0.057603687 | N20: 0.028801843 | O20: 0.11520737 | P20: 1.1616743 | Q20: 117.60753 | R20: 0.098886329 | S20: <0,01 | T20: 0.28801843 | U20: 0.067233103 | V20: 128.45622 | W20: <0,01 | X20: 0.001312404 | Y20: 1.2288786 | Z20: 0.1344086 | AA20: 0.010032642 | AB20: 2.9857911 | AC20: <0,01 | AD20: <0,01 | AE20: 17.473118 | AF20: 0.013172043 | AG20: 15.975422 | AH20: 0.63364055 | AI20: 2.9569892 | AJ20: <0,01 | AK20: 4.9155146
A21: EHU ION2768-20 | B21: =RIGHT(A21, LEN(A21)-7) -> 2768-20 | C21: =VLOOKUP(B21,'CEBAS-DEWOOD code'!A$2:B$302,2,FALSE) -> 155 | D21: =VLOOKUP(IONOMICS!C21,'Field Table'!A$2:E$661,3,FALSE) -> FS | E21: =VLOOKUP(IONOMICS!C21,'Field Table'!A$2:E$661,4,FALSE) -> 1 | F21: =VLOOKUP(IONOMICS!C21,'Field Table'!A$2:E$661,5,FALSE) -> 10 | G21: 11.153359 | H21: <0,01 | I21: <0,01 | J21: <0,01 | K21: <0,01 | L21: 0.1730038 | M21: 0.042247571 | N21: <0,01 | O21: 0.031685678 | P21: 0.90832277 | Q21: 8.0587241 | R21: 0.058291086 | S21: <0,01 | T21: 0.15842839 | U21: 0.033016477 | V21: 64.73384 | W21: <0,01 | X21: 0.00019011407 | Y21: 0.60202788 | Z21: 0.17955218 | AA21: 0.0044201521 | AB21: 1.6793409 | AC21: <0,01 | AD21: <0,01 | AE21: 63.455851 | AF21: 0.0094370511 | AG21: 8.861428 | AH21: 0.82382763 | AI21: <0,01 | AJ21: <0,01 | AK21: 2.4926067
A22: EHU ION2768-21 | B22: =RIGHT(A22, LEN(A22)-7) -> 2768-21 | C22: =VLOOKUP(B22,'CEBAS-DEWOOD code'!A$2:B$302,2,FALSE) -> 401 | D22: =VLOOKUP(IONOMICS!C22,'Field Table'!A$2:E$661,3,FALSE) -> FS | E22: =VLOOKUP(IONOMICS!C22,'Field Table'!A$2:E$661,4,FALSE) -> 4 | F22: =VLOOKUP(IONOMICS!C22,'Field Table'!A$2:E$661,5,FALSE) -> 25 | G22: 10.458959 | H22: 0.06619594 | I22: <0,01 | J22: <0,01 | K22: <0,01 | L22: 0.22032215 | M22: 0.19858782 | N22: 0.29788173 | O22: 0.17652251 | P22: 2.3499559 | Q22: 20.531774 | R22: 0.029446161 | S22: <0,01 | T22: 0.22065313 | U22: 0.023565899 | V22: 92.740512 | W22: <0,01 | X22: 0.00034090909 | Y22: 1.7652251 | Z22: 0.35304501 | AA22: 0.008434466 | AB22: 2.184466 | AC22: <0,01 | AD22: <0,01 | AE22: 34.521183 | AF22: 0.024646955 | AG22: 9.0688438 | AH22: 1.2577229 | AI22: 5.0970874 | AJ22: <0,01 | AK22: 4.5564872
A23: EHU ION2768-22 | B23: =RIGHT(A23, LEN(A23)-7) -> 2768-22 | C23: =VLOOKUP(B23,'CEBAS-DEWOOD code'!A$2:B$302,2,FALSE) -> 1 | D23: =VLOOKUP(IONOMICS!C23,'Field Table'!A$2:E$661,3,FALSE) -> AA | E23: =VLOOKUP(IONOMICS!C23,'Field Table'!A$2:E$661,4,FALSE) -> 1 | F23: =VLOOKUP(IONOMICS!C23,'Field Table'!A$2:E$661,5,FALSE) -> 25 | G23: 47.104106 | H23: <0,01 | I23: <0,01 | J23: <0,01 | K23: <0,01 | L23: 0.068572825 | M23: 0.036656891 | N23: <0,01 | O23: 0.29325513 | P23: 1.1363636 | Q23: 34.775171 | R23: 0.26344086 | S23: <0,01 | T23: 0.23216031 | U23: 0.018242913 | V23: 18.902737 | W23: <0,01 | X23: 0.00021871945 | Y23: 0.10997067 | Z23: 0.34213099 | AA23: 0.0016092375 | AB23: 7.1480938 | AC23: <0,01 | AD23: <0,01 | AE23: 75 | AF23: 0.0048130499 | AG23: 3.6656891 | AH23: 4.3377322 | AI23: <0,01 | AJ23: <0,01 | AK23: 3.2502444
A24: EHU ION2768-23 | B24: =RIGHT(A24, LEN(A24)-7) -> 2768-23 | C24: =VLOOKUP(B24,'CEBAS-DEWOOD code'!A$2:B$302,2,FALSE) -> 361 | D24: =VLOOKUP(IONOMICS!C24,'Field Table'!A$2:E$661,3,FALSE) -> AA | E24: =VLOOKUP(IONOMICS!C24,'Field Table'!A$2:E$661,4,FALSE) -> 2 | F24: =VLOOKUP(IONOMICS!C24,'Field Table'!A$2:E$661,5,FALSE) -> 25 | G24: 3.4872488 | H24: <0,01 | I24: <0,01 | J24: <0,01 | K24: <0,01 | L24: 0.044783617 | M24: 0.057959815 | N24: 0.048299845 | O24: 0.11591963 | P24: 0.88871716 | Q24: 6.6846986 | R24: 0.063475657 | S24: <0,01 | T24: 0.20285935 | U24: 0.0085625966 | V24: 18.151082 | W24: <0,01 | X24: 0.00051777434 | Y24: 0.0096599691 | Z24: 0.019319938 | AA24: 0.00075830757 | AB24: 1.4103555 | AC24: <0,01 | AD24: <0,01 | AE24: 3.6224884 | AF24: 0.0042445904 | AG24: 2.5598918 | AH24: 1.6518547 | AI24: <0,01 | AJ24: <0,01 | AK24: 3.3133694
A25: EHU ION2768-24 | B25: =RIGHT(A25, LEN(A25)-7) -> 2768-24 | C25: =VLOOKUP(B25,'CEBAS-DEWOOD code'!A$2:B$302,2,FALSE) -> 1072 | D25: =VLOOKUP(IONOMICS!C25,'Field Table'!A$2:E$661,3,FALSE) -> FS | E25: =VLOOKUP(IONOMICS!C25,'Field Table'!A$2:E$661,4,FALSE) -> 4 | F25: =VLOOKUP(IONOMICS!C25,'Field Table'!A$2:E$661,5,FALSE) -> 01 | G25: 34.869953 | H25: <0,01 | I25: <0,01 | J25: <0,01 | K25: <0,01 | L25: 0.49776786 | M25: 0.067934783 | N25: 0.048524845 | O25: 0.31055901 | P25: 2.7368012 | Q25: 20.652174 | R25: 0.040925854 | S25: <0,01 | T25: 0.14557453 | U25: 0.029473991 | V25: 129.75543 | W25: <0,01 | X25: 0.0022234084 | Y25: 0.51436335 | Z25: 1.251941 | AA25: 0.012121506 | AB25: 0.77639752 | AC25: <0,01 | AD25: <0,01 | AE25: 326.28106 | AF25: 0.022350543 | AG25: 35.636646 | AH25: 1.5139752 | AI25: <0,01 | AJ25: <0,01 | AK25: 10.869565
A26: EHU ION2768-25 | B26: =RIGHT(A26, LEN(A26)-7) -> 2768-25 | C26: =VLOOKUP(B26,'CEBAS-DEWOOD code'!A$2:B$302,2,FALSE) -> 410 | D26: =VLOOKUP(IONOMICS!C26,'Field Table'!A$2:E$661,3,FALSE) -> FS | E26: =VLOOKUP(IONOMICS!C26,'Field Table'!A$2:E$661,4,FALSE) -> 2 | F26: =VLOOKUP(IONOMICS!C26,'Field Table'!A$2:E$661,5,FALSE) -> 10 | G26: 1.89747 | H26: 0.13315579 | I26: <0,01 | J26: <0,01 | K26: <0,01 | L26: 0.1222814 | M26: 0.19973369 | N26: 0.12205948 | O26: 0.022192632 | P26: 0.98757213 | Q26: 6.4580559 | R26: 0.10788948 | S26: <0,01 | T26: 0.13315579 | U26: 0.033388815 | V26: 153.0182 | W26: <0,01 | X26: <0,01 | Y26: 0.8322237 | Z26: 0.16644474 | AA26: 0.0076165113 | AB26: 3.650688 | AC26: <0,01 | AD26: <0,01 | AE26: 8.3444296 | AF26: 0.011140701 | AG26: 7.6009765 | AH26: 0.47714159 | AI26: <0,01 | AJ26: <0,01 | AK26: 3.6617843
A27: EHU ION2768-26 | B27: =RIGHT(A27, LEN(A27)-7) -> 2768-26 | C27: =VLOOKUP(B27,'CEBAS-DEWOOD code'!A$2:B$302,2,FALSE) -> 76 | D27: =VLOOKUP(IONOMICS!C27,'Field Table'!A$2:E$661,3,FALSE) -> FS | E27: =VLOOKUP(IONOMICS!C27,'Field Table'!A$2:E$661,4,FALSE) -> 1 | F27: =VLOOKUP(IONOMICS!C27,'Field Table'!A$2:E$661,5,FALSE) -> 25 | G27: 12.842801 | H27: <0,01 | I27: <0,01 | J27: <0,01 | K27: <0,01 | L27: 0.09463761 | M27: 0.073457395 | N27: 0.085700294 | O27: 0.33055828 | P27: 1.4446621 | Q27: 18.217434 | R27: 0.1456905 | S27: <0,01 | T27: 0.28158668 | U27: 0.026738492 | V27: 62.487757 | W27: <0,01 | X27: 0.0074265426 | Y27: 0.82027424 | Z27: 0.18364349 | AA27: 0.0054113614 | AB27: 4.9951028 | AC27: <0,01 | AD27: <0,01 | AE27: 19.93144 | AF27: 0.010568071 | AG27: 7.2233105 | AH27: 4.4809011 | AI27: <0,01 | AJ27: <0,01 | AK27: 3.3055828
A28: EHU ION2768-27 | B28: =RIGHT(A28, LEN(A28)-7) -> 2768-27 | C28: =VLOOKUP(B28,'CEBAS-DEWOOD code'!A$2:B$302,2,FALSE) -> 1014 | D28: =VLOOKUP(IONOMICS!C28,'Field Table'!A$2:E$661,3,FALSE) -> AA | E28: =VLOOKUP(IONOMICS!C28,'Field Table'!A$2:E$661,4,FALSE) -> 2 | F28: =VLOOKUP(IONOMICS!C28,'Field Table'!A$2:E$661,5,FALSE) -> 01 | G28: 27.46344 | H28: 0.043523677 | I28: <0,01 | J28: <0,01 | K28: <0,01 | L28: 0.11298747 | M28: 0.16538997 | N28: <0,01 | O28: 0.19150418 | P28: 2.1587744 | Q28: 12.195334 | R28: 0.063849234 | S28: <0,01 | T28: 0.13927577 | U28: 0.017740251 | V28: 73.911908 | W28: <0,01 | X28: 0.00036472841 | Y28: 0.24373259 | Z28: 0.27855153 | AA28: 0.0056841922 | AB28: 0.8617688 | AC28: <0,01 | AD28: <0,01 | AE28: 26.540738 | AF28: 0.009670961 | AG28: 4.2305014 | AH28: 0.84435933 | AI28: <0,01 | AJ28: <0,01 | AK28: 10.219359
A29: EHU ION2768-28 | B29: =RIGHT(A29, LEN(A29)-7) -> 2768-28 | C29: =VLOOKUP(B29,'CEBAS-DEWOOD code'!A$2:B$302,2,FALSE) -> #N/A | D29: =VLOOKUP(IONOMICS!C29,'Field Table'!A$2:E$661,3,FALSE) -> #N/A | E29: =VLOOKUP(IONOMICS!C29,'Field Table'!A$2:E$661,4,FALSE) -> #N/A | F29: =VLOOKUP(IONOMICS!C29,'Field Table'!A$2:E$661,5,FALSE) -> #N/A | G29: 4.4871795 | H29: 0.10508617 | I29: <0,01 | J29: <0,01 | K29: <0,01 | L29: 0.10571669 | M29: 0.10508617 | N29: <0,01 | O29: <0,01 | P29: 1.1664565 | Q29: 3.3417402 | R29: 0.085834384 | S29: <0,01 | T29: 0.16813787 | U29: 0.061664565 | V29: 40.50021 | W29: <0,01 | X29: 0.00010718789 | Y29: 0.66204288 | Z29: 0.094577554 | AA29: 0.006504834 | AB29: 3.0369903 | AC29: <0,01 | AD29: <0,01 | AE29: 26.944094 | AF29: 0.010153426 | AG29: 9.4052123 | AH29: 0.39932745 | AI29: <0,01 | AJ29: <0,01 | AK29: 3.3837747
A30: EHU ION2768-29 | B30: =RIGHT(A30, LEN(A30)-7) -> 2768-29 | C30: =VLOOKUP(B30,'CEBAS-DEWOOD code'!A$2:B$302,2,FALSE) -> 189 | D30: =VLOOKUP(IONOMICS!C30,'Field Table'!A$2:E$661,3,FALSE) -> AA | E30: =VLOOKUP(IONOMICS!C30,'Field Table'!A$2:E$661,4,FALSE) -> 2 | F30: =VLOOKUP(IONOMICS!C30,'Field Table'!A$2:E$661,5,FALSE) -> 10 | G30: 7.6106842 | H30: 0.054884742 | I30: <0,01 | J30: <0,01 | K30: <0,01 | L30: 0.072639956 | M30: 0.073179656 | N30: <0,01 | O30: 0.027442371 | P30: 0.69520673 | Q30: 1.600805 | R30: 0.1126052 | S30: <0,01 | T30: 0.10062203 | U30: 0.015120746 | V30: 26.070252 | W30: <0,01 | X30: 0.00011525796 | Y30: 0.073179656 | Z30: 0.064032199 | AA30: 0.0015825101 | AB30: 2.0764727 | AC30: <0,01 | AD30: <0,01 | AE30: 2.5246981 | AF30: 0.0052003293 | AG30: 4.5554336 | AH30: 0.1920966 | AI30: <0,01 | AJ30: <0,01 | AK30: 3.4760337
A31: EHU ION2768-30 | B31: =RIGHT(A31, LEN(A31)-7) -> 2768-30 | C31: =VLOOKUP(B31,'CEBAS-DEWOOD code'!A$2:B$302,2,FALSE) -> 1063 | D31: =VLOOKUP(IONOMICS!C31,'Field Table'!A$2:E$661,3,FALSE) -> AA | E31: =VLOOKUP(IONOMICS!C31,'Field Table'!A$2:E$661,4,FALSE) -> 4 | F31: =VLOOKUP(IONOMICS!C31,'Field Table'!A$2:E$661,5,FALSE) -> 01 | G31: 102.39573 | H31: <0,01 | I31: <0,01 | J31: <0,01 | K31: <0,01 | L31: 0.23286991 | M31: 0.40963257 | N31: <0,01 | O31: 0.459285 | P31: 2.8550149 | Q31: 41.53426 | R31: 0.014039225 | S31: <0,01 | T31: 0.099304866 | U31: 0.018247269 | V31: 104.22046 | W31: <0,01 | X31: 0.0014374379 | Y31: 0.32274081 | Z31: 3.438431 | AA31: 0.0079568024 | AB31: 0.62065541 | AC31: <0,01 | AD31: <0,01 | AE31: 87.984111 | AF31: 0.019116187 | AG31: 10.327706 | AH31: 2.7929494 | AI31: <0,01 | AJ31: <0,01 | AK31: 19.401688
A32: EHU ION2768-31 | B32: =RIGHT(A32, LEN(A32)-7) -> 2768-31 | C32: =VLOOKUP(B32,'CEBAS-DEWOOD code'!A$2:B$302,2,FALSE) -> 380 | D32: =VLOOKUP(IONOMICS!C32,'Field Table'!A$2:E$661,3,FALSE) -> AA | E32: =VLOOKUP(IONOMICS!C32,'Field Table'!A$2:E$661,4,FALSE) -> 4 | F32: =VLOOKUP(IONOMICS!C32,'Field Table'!A$2:E$661,5,FALSE) -> 25 | G32: 8.4267564 | H32: 0.0093423019 | I32: <0,01 | J32: <0,01 | K32: <0,01 | L32: 0.14088191 | M32: 0.21487294 | N32: <0,01 | O32: 0.093423019 | P32: 1.9245142 | Q32: 6.4835575 | R32: 0.12677504 | S32: <0,01 | T32: 0.18684604 | U32: 0.020898729 | V32: 53.671525 | W32: <0,01 | X32: 0.00080810912 | Y32: 0.52316891 | Z32: 0.20553064 | AA32: 0.0028447309 | AB32: 1.4200299 | AC32: <0,01 | AD32: <0,01 | AE32: 9.1834828 | AF32: 0.007901719 | AG32: 10.650224 | AH32: 0.41106129 | AI32: <0,01 | AJ32: <0,01 | AK32: 6.2406577
A33: EHU ION2768-32 | B33: =RIGHT(A33, LEN(A33)-7) -> 2768-32 | C33: =VLOOKUP(B33,'CEBAS-DEWOOD code'!A$2:B$302,2,FALSE) -> 1005 | D33: =VLOOKUP(IONOMICS!C33,'Field Table'!A$2:E$661,3,FALSE) -> FS | E33: =VLOOKUP(IONOMICS!C33,'Field Table'!A$2:E$661,4,FALSE) -> 2 | F33: =VLOOKUP(IONOMICS!C33,'Field Table'!A$2:E$661,5,FALSE) -> 01 | G33: 14.134972 | H33: 0.046382189 | I33: <0,01 | J33: <0,01 | K33: <0,01 | L33: 0.26495826 | M33: 0.069573284 | N33: <0,01 | O33: 0.24350649 | P33: 2.1683673 | Q33: 11.989796 | R33: 0.082224026 | S33: <0,01 | T33: 0.24350649 | U33: 0.030820965 | V33: 78.849722 | W33: <0,01 | X33: 0.00048817254 | Y33: 1.3218924 | Z33: 0.68413729 | AA33: 0.014413265 | AB33: 2.8872913 | AC33: <0,01 | AD33: <0,01 | AE33: 365.02783 | AF33: 0.019399351 | AG33: 17.312152 | AH33: 1.1131725 | AI33: <0,01 | AJ33: <0,01 | AK33: 4.2323748
A34: EHU ION2768-33 | B34: =RIGHT(A34, LEN(A34)-7) -> 2768-33 | C34: =VLOOKUP(B34,'CEBAS-DEWOOD code'!A$2:B$302,2,FALSE) -> 110 | D34: =VLOOKUP(IONOMICS!C34,'Field Table'!A$2:E$661,3,FALSE) -> AA | E34: =VLOOKUP(IONOMICS!C34,'Field Table'!A$2:E$661,4,FALSE) -> 2 | F34: =VLOOKUP(IONOMICS!C34,'Field Table'!A$2:E$661,5,FALSE) -> 25 | G34: 6.0918114 | H34: <0,01 | I34: <0,01 | J34: <0,01 | K34: <0,01 | L34: 0.03983871 | M34: 0.037220844 | N34: <0,01 | O34: <0,01 | P34: 0.79404467 | Q34: 3.8585608 | R34: 0.077679901 | S34: <0,01 | T34: 0.22332506 | U34: 0.0085260546 | V34: 16.401985 | W34: <0,01 | X34: <0,01 | Y34: 0.074441687 | Z34: 0.12406948 | AA34: 0.00064888337 | AB34: 1.5384615 | AC34: <0,01 | AD34: <0,01 | AE34: 5.2729529 | AF34: 0.0044689826 | AG34: 2.6426799 | AH34: 0.74441687 | AI34: <0,01 | AJ34: <0,01 | AK34: 2.8039702
A35: EHU ION2768-34 | B35: =RIGHT(A35, LEN(A35)-7) -> 2768-34 | C35: =VLOOKUP(B35,'CEBAS-DEWOOD code'!A$2:B$302,2,FALSE) -> #N/A | D35: =VLOOKUP(IONOMICS!C35,'Field Table'!A$2:E$661,3,FALSE) -> #N/A | E35: =VLOOKUP(IONOMICS!C35,'Field Table'!A$2:E$661,4,FALSE) -> #N/A | F35: =VLOOKUP(IONOMICS!C35,'Field Table'!A$2:E$661,5,FALSE) -> #N/A | G35: 8.1960784 | H35: 0.11764706 | I35: <0,01 | J35: <0,01 | K35: <0,01 | L35: 0.22813725 | M35: 0.098039216 | N35: 0.049019608 | O35: 0.16666667 | P35: 1.3627451 | Q35: 2.5 | R35: 0.025205882 | S35: <0,01 | T35: 0.14705882 | U35: 0.045892157 | V35: 87.04902 | W35: <0,01 | X35: 0.00054705882 | Y35: 0.17647059 | Z35: 0.40196078 | AA35: 0.0030882353 | AB35: 0.46078431 | AC35: <0,01 | AD35: <0,01 | AE35: 4.7254902 | AF35: 0.0088303922 | AG35: 11.313725 | AH35: 0.39215686 | AI35: <0,01 | AJ35: <0,01 | AK35: 6.6862745
A36: EHU ION2768-35 | B36: =RIGHT(A36, LEN(A36)-7) -> 2768-35 | C36: =VLOOKUP(B36,'CEBAS-DEWOOD code'!A$2:B$302,2,FALSE) -> 369 | D36: =VLOOKUP(IONOMICS!C36,'Field Table'!A$2:E$661,3,FALSE) -> AA | E36: =VLOOKUP(IONOMICS!C36,'Field Table'!A$2:E$661,4,FALSE) -> 2 | F36: =VLOOKUP(IONOMICS!C36,'Field Table'!A$2:E$661,5,FALSE) -> 10 | G36: 4.4295863 | H36: <0,01 | I36: <0,01 | J36: <0,01 | K36: <0,01 | L36: 0.036011283 | M36: 0.073129962 | N36: <0,01 | O36: 0.031341412 | P36: 0.86711241 | Q36: 4.3877977 | R36: 0.062755955 | S36: <0,01 | T36: 0.27162557 | U36: 0.008269954 | V36: 16.391559 | W36: <0,01 | X36: <0,01 | Y36: <0,01 | Z36: 0.11491851 | AA36: 0.0052183452 | AB36: 0.92979524 | AC36: <0,01 | AD36: <0,01 | AE36: 8.817384 | AF36: 0.0043000418 | AG36: 2.2983702 | AH36: 0.64772252 | AI36: <0,01 | AJ36: <0,01 | AK36: 3.7609695
A37: EHU ION2768-36 | B37: =RIGHT(A37, LEN(A37)-7) -> 2768-36 | C37: =VLOOKUP(B37,'CEBAS-DEWOOD code'!A$2:B$302,2,FALSE) -> 1038 | D37: =VLOOKUP(IONOMICS!C37,'Field Table'!A$2:E$661,3,FALSE) -> AA | E37: =VLOOKUP(IONOMICS!C37,'Field Table'!A$2:E$661,4,FALSE) -> 2 | F37: =VLOOKUP(IONOMICS!C37,'Field Table'!A$2:E$661,5,FALSE) -> 01 | G37: 92.814438 | H37: <0,01 | I37: <0,01 | J37: <0,01 | K37: <0,01 | L37: 0.34078831 | M37: 0.47608503 | N37: 0.011071745 | O37: 5.8458813 | P37: 2.9229407 | Q37: 54.140833 | R37: 0.072752436 | S37: <0,01 | T37: 0.28786537 | U37: 0.038319309 | V37: 103.29938 | W37: <0,01 | X37: 0.0004428698 | Y37: 0.62001771 | Z37: 1.9596988 | AA37: 0.012632861 | AB37: 1.4614703 | AC37: <0,01 | AD37: <0,01 | AE37: 52.900797 | AF37: 0.018954827 | AG37: 15.73295 | AH37: 1.7604074 | AI37: <0,01 | AJ37: <0,01 | AK37: 31.166962
A38: EHU ION2768-37 | B38: =RIGHT(A38, LEN(A38)-7) -> 2768-37 | C38: =VLOOKUP(B38,'CEBAS-DEWOOD code'!A$2:B$302,2,FALSE) -> 268 | D38: =VLOOKUP(IONOMICS!C38,'Field Table'!A$2:E$661,3,FALSE) -> FS | E38: =VLOOKUP(IONOMICS!C38,'Field Table'!A$2:E$661,4,FALSE) -> 2 | F38: =VLOOKUP(IONOMICS!C38,'Field Table'!A$2:E$661,5,FALSE) -> 01 | G38: 10.279354 | H38: 0.94936709 | I38: 0.2837189 | J38: <0,01 | K38: <0,01 | L38: 0.067263204 | M38: 0.75294631 | N38: 0.42557835 | O38: 0.32736796 | P38: 1.4295068 | Q38: 7.8240943 | R38: 0.10440856 | S38: <0,01 | T38: 0.49105194 | U38: 0.018408992 | V38: 30.117852 | W38: 1.7241379 | X38: 0.00063945875 | Y38: 0.46922741 | Z38: 1.7459625 | AA38: 0.002220646 | AB38: 1.9205587 | AC38: 1.7568747 | AD38: <0,01 | AE38: 14.720646 | AF38: 0.0062123527 | AG38: 3.7756438 | AH38: 1.3094718 | AI38: <0,01 | AJ38: 0.16368398 | AK38: 4.8886949
A39: EHU ION2768-38 | B39: =RIGHT(A39, LEN(A39)-7) -> 2768-38 | C39: =VLOOKUP(B39,'CEBAS-DEWOOD code'!A$2:B$302,2,FALSE) -> 157 | D39: =VLOOKUP(IONOMICS!C39,'Field Table'!A$2:E$661,3,FALSE) -> FS | E39: =VLOOKUP(IONOMICS!C39,'Field Table'!A$2:E$661,4,FALSE) -> 4 | F39: =VLOOKUP(IONOMICS!C39,'Field Table'!A$2:E$661,5,FALSE) -> 10 | G39: 3.8348624 | H39: 0.14678899 | I39: 0.0091743119 | J39: <0,01 | K39: <0,01 | L39: 0.089045872 | M39: 0.14678899 | N39: 0.082568807 | O39: 0.11009174 | P39: 1.1192661 | Q39: 2.8073394 | R39: 0.038165138 | S39: <0,01 | T39: 0.19266055 | U39: 0.046605505 | V39: 32.311927 | W39: <0,01 | X39: 0.00015229358 | Y39: 0.44036697 | Z39: 0.21100917 | AA39: 0.0039844037 | AB39: 1.5688073 | AC39: <0,01 | AD39: <0,01 | AE39: 11.06422 | AF39: 0.0074816514 | AG39: 10.330275 | AH39: 0.3853211 | AI39: <0,01 | AJ39: <0,01 | AK39: 2.4311927
A40: EHU ION2768-39 | B40: =RIGHT(A40, LEN(A40)-7) -> 2768-39 | C40: =VLOOKUP(B40,'CEBAS-DEWOOD code'!A$2:B$302,2,FALSE) -> 1035 | D40: =VLOOKUP(IONOMICS!C40,'Field Table'!A$2:E$661,3,FALSE) -> FS | E40: =VLOOKUP(IONOMICS!C40,'Field Table'!A$2:E$661,4,FALSE) -> 2 | F40: =VLOOKUP(IONOMICS!C40,'Field Table'!A$2:E$661,5,FALSE) -> 01 | G40: 11.705653 | H40: 0.038986355 | I40: <0,01 | J40: <0,01 | K40: <0,01 | L40: 0.18430799 | M40: 0.11695906 | N40: 0.058479532 | O40: 0.1754386 | P40: 2.2709552 | Q40: 9.5224172 | R40: 0.10380117 | S40: <0,01 | T40: 0.26315789 | U40: 0.021276803 | V40: 58.382066 | W40: <0,01 | X40: 0.00067348928 | Y40: 0.5165692 | Z40: 0.36062378 | AA40: 0.026978558 | AB40: 2.6705653 | AC40: <0,01 | AD40: <0,01 | AE40: 344.05458 | AF40: 0.019580897 | AG40: 10.847953 | AH40: 0.49707602 | AI40: <0,01 | AJ40: <0,01 | AK40: 4.2300195
...

Sheet CEBAS-DEWOOD code
A1: CODE CEBAS | B1: CODE DEWOOD
A2: 2775-24 | B2: 42
A3: 2775-13 | B3: 1034
A4: 2775-28 | B4: 130
A5: 2775-16 | B5: 1025
A6: 2775-30 | B6: 170
A7: 2775-14 | B7: 1058
A8: 2775-9 | B8: 378
A9: 2775-23 | B9: 1015
A10: 2775-17 | B10: 331
A11: 2775-7 | B11: 1010
A12: 2775-1 | B12: 187
A13: 2775-4 | B13: 1057
... A29: 2775-5 | B29: 1013
A30: 2775-…......... | B30: ….........
A31: 2775-…......... | B31: ….........
A32: 2768-1 | B32: 114
A33: 2768-13 | B33: 382
A34: 2768-3 | B34: 37
A35: 2768-2 | B35: 364
A36: 2768-16 | B36: 190
A37: 2768-11 | B37: 381
A38: 2768-15 | B38: 176
A39: 2768-12 | B39: 75
A40: 2768-9 | B40: 137
A41: 2768-18 | B41: 1085
A42: 2768-4 | B42: 172
A43: 2768-10 | B43: 1090
... A298: 2768-113 | B298: 333
A299: 2768-….............. | B299: …..............
A300: 2768-….............. | B300: …..............
A301: 2768-….............. | B301: …..............
A302: 2768-….............. | B302: …..............

Sheet Field Table
A1: LABEL | B1: Code | C1: Species | D1: Class | E1: Diameter
A2: 1 | B2: 25-P1S1C1AA | C2: =RIGHT(LEFT(B2,11),2) -> AA | D2: =RIGHT(LEFT(B2,9),1) -> 1 | E2: =LEFT(B2,2) -> 25
A3: 2 | B3: 25-P1S1C2AA | C3: =RIGHT(LEFT(B3,11),2) -> AA | D3: =RIGHT(LEFT(B3,9),1) -> 2 | E3: =LEFT(B3,2) -> 25
A4: 3 | B4: 25-P1S1C4AA | C4: =RIGHT(LEFT(B4,11),2) -> AA | D4: =RIGHT(LEFT(B4,9),1) -> 4 | E4: =LEFT(B4,2) -> 25
A5: 4 | B5: 25-P1S1C1FS | C5: =RIGHT(LEFT(B5,11),2) -> FS | D5: =RIGHT(LEFT(B5,9),1) -> 1 | E5: =LEFT(B5,2) -> 25
A6: 5 | B6: 25-P1S1C2FS | C6: =RIGHT(LEFT(B6,11),2) -> FS | D6: =RIGHT(LEFT(B6,9),1) -> 2 | E6: =LEFT(B6,2) -> 25
A7: 6 | B7: 25-P1S1C4FS | C7: =RIGHT(LEFT(B7,11),2) -> FS | D7: =RIGHT(LEFT(B7,9),1) -> 4 | E7: =LEFT(B7,2) -> 25
A8: 37 | B8: 25-P1S2C1AA | C8: =RIGHT(LEFT(B8,11),2) -> AA | D8: =RIGHT(LEFT(B8,9),1) -> 1 | E8: =LEFT(B8,2) -> 25
A9: 38 | B9: 25-P1S2C2AA | C9: =RIGHT(LEFT(B9,11),2) -> AA | D9: =RIGHT(LEFT(B9,9),1) -> 2 | E9: =LEFT(B9,2) -> 25
A10: 39 | B10: 25-P1S2C4AA | C10: =RIGHT(LEFT(B10,11),2) -> AA | D10: =RIGHT(LEFT(B10,9),1) -> 4 | E10: =LEFT(B10,2) -> 25
A11: 40 | B11: 25-P1S2C1FS | C11: =RIGHT(LEFT(B11,11),2) -> FS | D11: =RIGHT(LEFT(B11,9),1) -> 1 | E11: =LEFT(B11,2) -> 25
A12: 41 | B12: 25-P1S2C2FS | C12: =RIGHT(LEFT(B12,11),2) -> FS | D12: =RIGHT(LEFT(B12,9),1) -> 2 | E12: =LEFT(B12,2) -> 25
A13: 42 | B13: 25-P1S2C4FS | C13: =RIGHT(LEFT(B13,11),2) -> FS | D13: =RIGHT(LEFT(B13,9),1) -> 4 | E13: =LEFT(B13,2) -> 25
... A571: 563 | B571: 01-P6S5C4FS-Sp | C571: =RIGHT(LEFT(B571,11),2) -> FS | D571: =RIGHT(LEFT(B571,9),1) -> 4 | E571: =LEFT(B571,2) -> 01
A572: 1001 | B572: 11AA1 | C572: =RIGHT(LEFT(B572,4),2) -> AA | D572: =RIGHT(LEFT(B572,9),1) -> 1 | E572: 01
A573: 1002 | B573: 11AA2 | C573: =RIGHT(LEFT(B573,4),2) -> AA | D573: =RIGHT(LEFT(B573,9),1) -> 2 | E573: 01
A574: 1003 | B574: 11AA4 | C574: =RIGHT(LEFT(B574,4),2) -> AA | D574: =RIGHT(LEFT(B574,9),1) -> 4 | E574: 01
A575: 1004 | B575: 11FS1 | C575: =RIGHT(LEFT(B575,4),2) -> FS | D575: =RIGHT(LEFT(B575,9),1) -> 1 | E575: 01
A576: 1005 | B576: 11FS2 | C576: =RIGHT(LEFT(B576,4),2) -> FS | D576: =RIGHT(LEFT(B576,9),1) -> 2 | E576: 01
A577: 1006 | B577: 11FS4 | C577: =RIGHT(LEFT(B577,4),2) -> FS | D577: =RIGHT(LEFT(B577,9),1) -> 4 | E577: 01
A578: 1007 | B578: 12AA1 | C578: =RIGHT(LEFT(B578,4),2) -> AA | D578: =RIGHT(LEFT(B578,9),1) -> 1 | E578: 01
A579: 1008 | B579: 12AA2 | C579: =RIGHT(LEFT(B579,4),2) -> AA | D579: =RIGHT(LEFT(B579,9),1) -> 2 | E579: 01
A580: 1009 | B580: 12AA4 | C580: =RIGHT(LEFT(B580,4),2) -> AA | D580: =RIGHT(LEFT(B580,9),1) -> 4 | E580: 01
A581: 1010 | B581: 12FS1 | C581: =RIGHT(LEFT(B581,4),2) -> FS | D581: =RIGHT(LEFT(B581,9),1) -> 1 | E581: 01
A582: 1011 | B582: 12FS2 | C582: =RIGHT(LEFT(B582,4),2) -> FS | D582: =RIGHT(LEFT(B582,9),1) -> 2 | E582: 01
A583: 1012 | B583: 12FS4 | C583: =RIGHT(LEFT(B583,4),2) -> FS | D583: =RIGHT(LEFT(B583,9),1) -> 4 | E583: 01
... A661: 1090 | B661: 65FS4 | C661: =RIGHT(LEFT(B661,4),2) -> FS | D661: =RIGHT(LEFT(B661,9),1) -> 4 | E661: 01
